Workbook

Sheet A组
A1: date | B1: country | C1: userid | D1: username | E1: register_time | F1: Total Stake | G1: Total Stake on Sports | H1: Total Stake on Games | I1: Total GGR | J1: Total Sports GGR | K1: Total Gaming GGR | L1: Total Deposit (usd) | M1: Total Deposit (local) | N1: The latest 90days Deposit (usd) | O1: The latest 90days Deposit (local) | P1: User Preference | Q1: deposit_category | R1: label | S1: No-Deposit Sports Coupon(odd>2.5) | T1: casinobonus | U1: VIP-type | V1: sex | W1: first_name | X1: last_name | Y1: birthday | Z1: temp_birthday | AA1: email | AB1: 号段 | AC1: 通讯商
A2: 2026-06-08 | B2: gh | C2: 20937650 | D2: 233200425461 | E2: 46045.916 | F2: 601.52 | G2: 0.08 | H2: 601.45 | I2: 31.31 | J2: -0.03 | K2: 31.34 | L2: 139.38 | M2: 1812 | N2: 123.62 | O2: 1607 | P2: casino-user | Q2: [50,1000) | R2: Group A | S2: 0 | T2: 0 | U2: 0 | AB2: 20 | AC2: Telecel
A3: 2026-06-08 | B3: gh | C3: 11241392 | D3: 233202423882 | E3: 45238.629 | F3: 0 | G3: 0 | H3: 0 | I3: 0 | J3: 0 | K3: 0 | L3: 192.31 | M3: 2500 | N3: 0 | O3: 0 | P3: unknown | Q3: [50,1000) | R3: Group A | S3: 120 | T3: 0 | U3: 0 | AB3: 20 | AC3: Telecel
A4: 2026-06-08 | B4: gh | C4: 6855101 | D4: 233500578321 | E4: 44611.508 | F4: 13871.94 | G4: 3.54 | H4: 13868.4 | I4: -282.77 | J4: 3.54 | K4: -286.31 | L4: 1661.46 | M4: 21599 | N4: 710.23 | O4: 9233 | P4: aviator-user | Q4: [1000,10w) | R4: Group A | S4: 0 | T4: 0 | U4: 0 | AB4: 50 | AC4: Telecel
A5: 2026-06-08 | B5: gh | C5: 22913470 | D5: 233503326514 | E5: 46159.657 | F5: 0.08 | G5: 0 | H5: 0.08 | I5: 0.08 | J5: 0 | K5: 0.08 | L5: 60 | M5: 780 | N5: 60 | O5: 780 | P5: casino-user | Q5: [50,1000) | R5: Group A | S5: 0 | T5: 0 | U5: 0 | AB5: 50 | AC5: Telecel
A6: 2026-06-08 | B6: gh | C6: 22843761 | D6: 233506502760 | E6: 46155.296 | F6: 813.54 | G6: 0 | H6: 813.54 | I6: 93.07 | J6: 0 | K6: 93.07 | L6: 137 | M6: 1781 | N6: 137 | O6: 1781 | P6: casino-user | Q6: [50,1000) | R6: Group A | S6: 0 | T6: 0 | U6: 0 | AB6: 50 | AC6: Telecel
A7: 2026-06-08 | B7: gh | C7: 11240940 | D7: 233507814734 | E7: 45238.607 | F7: 0 | G7: 0 | H7: 0 | I7: 0 | J7: 0 | K7: 0 | L7: 192.31 | M7: 2500 | N7: 0 | O7: 0 | P7: unknown | Q7: [50,1000) | R7: Group A | S7: 120 | T7: 0 | U7: 0 | AB7: 50 | AC7: Telecel
A8: 2026-06-08 | B8: gh | C8: 21802200 | D8: 233240254349 | E8: 46090.992 | F8: 546.31 | G8: 0.23 | H8: 546.08 | I8: 38.36 | J8: -0.39 | K8: 38.75 | L8: 77.38 | M8: 1006 | N8: 77.38 | O8: 1006 | P8: casino-user | Q8: [50,1000) | R8: Group A | S8: 0 | T8: 0 | U8: 0 | AB8: 24 | AC8: MTN
A9: 2026-06-08 | B9: gh | C9: 22978641 | D9: 233243952996 | E9: 46164.335 | F9: 5306.65 | G9: 0.08 | H9: 5306.58 | I9: 1900.81 | J9: 0.08 | K9: 1900.74 | L9: 1900.85 | M9: 24711 | N9: 1900.85 | O9: 24711 | P9: aviator-user | Q9: [1000,10w) | R9: Group A | S9: 0 | T9: 0 | U9: 0 | AB9: 24 | AC9: MTN
A10: 2026-06-08 | B10: gh | C10: 22818780 | D10: 233248914647 | E10: 46153.04 | F10: 384.62 | G10: 0 | H10: 384.62 | I10: 384.62 | J10: 0 | K10: 384.62 | L10: 384.62 | M10: 5000 | N10: 384.62 | O10: 5000 | P10: aviator-user | Q10: [50,1000) | R10: Group A | S10: 0 | T10: 0 | U10: 0 | AB10: 24 | AC10: MTN
A11: 2026-06-08 | B11: gh | C11: 22742322 | D11: 233256999078 | E11: 46148.132 | F11: 589.57 | G11: 0 | H11: 589.57 | I11: 20.67 | J11: 0 | K11: 20.67 | L11: 170.77 | M11: 2220 | N11: 170.77 | O11: 2220 | P11: casino-user | Q11: [50,1000) | R11: Group A | S11: 0 | T11: 0 | U11: 0 | AB11: 25 | AC11: MTN
A12: 2026-06-08 | B12: gh | C12: 20291542 | D12: 233257286401 | E12: 46015.344 | F12: 394.58 | G12: 5.85 | H12: 388.74 | I12: 31.53 | J12: 2.96 | K12: 28.57 | L12: 55.92 | M12: 727 | N12: 0.38 | O12: 5 | P12: casino-user | Q12: [50,1000) | R12: Group A | S12: 0 | T12: 0 | U12: 0 | AB12: 25 | AC12: MTN
A13: 2026-06-08 | B13: gh | C13: 16346011 | D13: 233257564352 | E13: 45769.07 | F13: 26964.28 | G13: 53.31 | H13: 26910.98 | I13: 1148.53 | J13: 53.31 | K13: 1095.22 | L13: 4923.69 | M13: 64008 | N13: 1960.31 | O13: 25484 | P13: aviator-user | Q13: [1000,10w) | R13: Group A | S13: 0 | T13: 0 | U13: 1 | V13: 1 | AB13: 25 | AC13: MTN
A14: 2026-06-08 | B14: gh | C14: 19820951 | D14: 233257685762 | E14: 45992.293 | F14: 11861.52 | G14: 0 | H14: 11861.52 | I14: 260.41 | J14: 0 | K14: 260.41 | L14: 1264.08 | M14: 16433 | N14: 61.92 | O14: 805 | P14: aviator-user | Q14: [1000,10w) | R14: Group A | S14: 0 | T14: 0 | U14: 0 | AB14: 25 | AC14: MTN
A15: 2026-06-08 | B15: gh | C15: 18715910 | D15: 233530876873 | E15: 45929.45 | F15: 1664.84 | G15: 7.08 | H15: 1657.77 | I15: 104.29 | J15: 1.14 | K15: 103.14 | L15: 258 | M15: 3354 | N15: 9.23 | O15: 120 | P15: casino-user | Q15: [50,1000) | R15: Group A | S15: 0 | T15: 0 | U15: 0 | AB15: 53 | AC15: MTN
A16: 2026-06-08 | B16: gh | C16: 20948881 | D16: 233531138233 | E16: 46046.631 | F16: 1200.21 | G16: 6.15 | H16: 1193.13 | I16: 157.78 | J16: 3.57 | K16: 154.21 | L16: 440.77 | M16: 5730 | N16: 328.69 | O16: 4273 | P16: casino-user | Q16: [50,1000) | R16: Group A | S16: 0 | T16: 0 | U16: 0 | AB16: 53 | AC16: MTN
A17: 2026-06-08 | B17: gh | C17: 13666322 | D17: 233531439036 | E17: 45546.753 | F17: 13124.32 | G17: 3004.86 | H17: 10119.46 | I17: 876.37 | J17: 60.48 | K17: 815.89 | L17: 4562.38 | M17: 59311 | N17: 752.85 | O17: 9787 | P17: bet&casino-user | Q17: [1000,10w) | R17: Group A | S17: 500 | T17: 0 | U17: 0 | AB17: 53 | AC17: MTN
A18: 2026-06-08 | B18: gh | C18: 20538991 | D18: 233531966836 | E18: 46026.563 | F18: 89.35 | G18: 56.6 | H18: 32.75 | I18: 4.65 | J18: 3.67 | K18: 0.97 | L18: 56.85 | M18: 739 | N18: 26.69 | O18: 347 | P18: bet&casino-user | Q18: [50,1000) | R18: Group A | S18: 120 | T18: 0 | U18: 0 | AB18: 53 | AC18: MTN
A19: 2026-06-08 | B19: gh | C19: 23003012 | D19: 233535425471 | E19: 46166.371 | F19: 3439.19 | G19: 0 | H19: 3439.19 | I19: 340.82 | J19: 0 | K19: 340.82 | L19: 496.15 | M19: 6450 | N19: 496.15 | O19: 6450 | P19: aviator-user | Q19: [50,1000) | R19: Group A | S19: 0 | T19: 0 | U19: 0 | AB19: 53 | AC19: MTN
A20: 2026-06-08 | B20: gh | C20: 22487841 | D20: 233535831756 | E20: 46130.258 | F20: 653.63 | G20: 0 | H20: 653.63 | I20: 16.15 | J20: 0 | K20: 16.15 | L20: 74.62 | M20: 970 | N20: 74.62 | O20: 970 | P20: casino-user | Q20: [50,1000) | R20: Group A | S20: 0 | T20: 0 | U20: 0 | AB20: 53 | AC20: MTN
A21: 2026-06-08 | B21: gh | C21: 17640241 | D21: 233537499088 | E21: 45868.011 | F21: 3709.24 | G21: 5.77 | H21: 3701.62 | I21: 182.81 | J21: 3.33 | K21: 179.48 | L21: 627.69 | M21: 8160 | N21: 286 | O21: 3718 | P21: casino-user | Q21: [50,1000) | R21: Group A | S21: 0 | T21: 0 | U21: 0 | AB21: 53 | AC21: MTN
A22: 2026-06-08 | B22: gh | C22: 21642371 | D22: 233537704967 | E22: 46082.693 | F22: 3185.59 | G22: 0 | H22: 3185.59 | I22: 180.68 | J22: 0 | K22: 180.68 | L22: 629.08 | M22: 8178 | N22: 533.69 | O22: 6938 | P22: casino-user | Q22: [50,1000) | R22: Group A | S22: 0 | T22: 0 | U22: 0 | AB22: 53 | AC22: MTN
A23: 2026-06-08 | B23: gh | C23: 20169110 | D23: 233539043315 | E23: 46008.791 | F23: 2346.51 | G23: 7.72 | H23: 2338.09 | I23: 140.2 | J23: -0.59 | K23: 140.79 | L23: 603.54 | M23: 7846 | N23: 319.15 | O23: 4149 | P23: casino-user | Q23: [50,1000) | R23: Group A | S23: 0 | T23: 0 | U23: 0 | AB23: 53 | AC23: MTN
A24: 2026-06-08 | B24: gh | C24: 22362211 | D24: 233539614598 | E24: 46122.726 | F24: 163.6 | G24: 0 | H24: 163.6 | I24: 31.53 | J24: 0 | K24: 31.53 | L24: 70 | M24: 910 | N24: 70 | O24: 910 | P24: casino-user | Q24: [50,1000) | R24: Group A | S24: 0 | T24: 0 | U24: 0 | AB24: 53 | AC24: MTN
A25: 2026-06-08 | B25: gh | C25: 19307471 | D25: 233542275666 | E25: 45967.707 | F25: 103.21 | G25: 15.93 | H25: 87.27 | I25: 37.92 | J25: 14 | K25: 23.92 | L25: 56.54 | M25: 735 | N25: 33.92 | O25: 441 | P25: bet&casino-user | Q25: [50,1000) | R25: Group A | S25: 120 | T25: 0 | U25: 0 | AB25: 54 | AC25: MTN
A26: 2026-06-08 | B26: gh | C26: 22317092 | D26: 233544687595 | E26: 46120.867 | F26: 140.15 | G26: 0 | H26: 140.15 | I26: -16.47 | J26: 0 | K26: -16.47 | L26: 58.92 | M26: 766 | N26: 58.92 | O26: 766 | P26: aviator-user | Q26: [50,1000) | R26: Group A | S26: 0 | T26: 0 | U26: 0 | AB26: 54 | AC26: MTN
A27: 2026-06-08 | B27: gh | C27: 19137112 | D27: 233544979077 | E27: 45956.742 | F27: 74748.59 | G27: 0 | H27: 74748.59 | I27: 3443.81 | J27: 0 | K27: 3443.81 | L27: 5996.15 | M27: 77950 | N27: 3642.46 | O27: 47352 | P27: casino-user | Q27: [1000,10w) | R27: Group A | S27: 0 | T27: 0 | U27: 1 | V27: 1 | AB27: 54 | AC27: MTN
A28: 2026-06-08 | B28: gh | C28: 5832722 | D28: 233545295774 | E28: 44522.556 | F28: 114.31 | G28: 5.38 | H28: 108.92 | I28: 13.05 | J28: -13.87 | K28: 26.92 | L28: 51.54 | M28: 670 | N28: 15.38 | O28: 200 | P28: aviator-user | Q28: [50,1000) | R28: Group A | S28: 0 | T28: 0 | U28: 0 | AB28: 54 | AC28: MTN
A29: 2026-06-08 | B29: gh | C29: 19569981 | D29: 233545807815 | E29: 45980.548 | F29: 2098.99 | G29: 0 | H29: 2098.99 | I29: 214.22 | J29: 0 | K29: 214.22 | L29: 426.46 | M29: 5544 | N29: 311.85 | O29: 4054 | P29: casino-user | Q29: [50,1000) | R29: Group A | S29: 0 | T29: 0 | U29: 0 | AB29: 54 | AC29: MTN
A30: 2026-06-08 | B30: gh | C30: 14873540 | D30: 233548155384 | E30: 45625.071 | F30: 33457.13 | G30: 115.82 | H30: 33341.31 | I30: 812.48 | J30: 49.33 | K30: 763.15 | L30: 7091.54 | M30: 92190 | N30: 4053.46 | O30: 52695 | P30: aviator-user | Q30: [1000,10w) | R30: Group A | S30: 0 | T30: 0 | U30: 1 | V30: 1 | AB30: 54 | AC30: MTN
A31: 2026-06-08 | B31: gh | C31: 18738320 | D31: 233548694876 | E31: 45931.26 | F31: 1555.58 | G31: 1.08 | H31: 1554.51 | I31: 82.13 | J31: 1.08 | K31: 81.06 | L31: 103.46 | M31: 1345 | N31: 59.85 | O31: 778 | P31: aviator-user | Q31: [50,1000) | R31: Group A | S31: 0 | T31: 0 | U31: 0 | AB31: 54 | AC31: MTN
A32: 2026-06-08 | B32: gh | C32: 16073481 | D32: 233548989747 | E32: 45744.806 | F32: 714.83 | G32: 0 | H32: 714.83 | I32: -10.1 | J32: 0 | K32: -10.1 | L32: 331.54 | M32: 4310 | N32: 0 | O32: 0 | P32: aviator-user | Q32: [50,1000) | R32: Group A | S32: 0 | T32: 0 | U32: 0 | AB32: 54 | AC32: MTN
A33: 2026-06-08 | B33: gh | C33: 21356012 | D33: 233549920355 | E33: 46068.975 | F33: 512.05 | G33: 171.17 | H33: 340.88 | I33: 148.65 | J33: 116.18 | K33: 32.47 | L33: 232.62 | M33: 3024 | N33: 155.92 | O33: 2027 | P33: bet&casino-user | Q33: [50,1000) | R33: Group A | S33: 120 | T33: 0 | U33: 0 | AB33: 54 | AC33: MTN
A34: 2026-06-08 | B34: gh | C34: 22923760 | D34: 233551995862 | E34: 46160.615 | F34: 611.47 | G34: 0 | H34: 611.47 | I34: 16.51 | J34: 0 | K34: 16.51 | L34: 78.46 | M34: 1020 | N34: 78.46 | O34: 1020 | P34: aviator-user | Q34: [50,1000) | R34: Group A | S34: 0 | T34: 0 | U34: 0 | AB34: 55 | AC34: MTN
A35: 2026-06-08 | B35: gh | C35: 8899321 | D35: 233552808730 | E35: 44856.409 | F35: 803.47 | G35: 0 | H35: 803.47 | I35: -74.31 | J35: 0 | K35: -33.92 | L35: 257.31 | M35: 3345 | N35: 0 | O35: 0 | P35: casino-user | Q35: [50,1000) | R35: Group A | S35: 0 | T35: 0 | U35: 0 | AB35: 55 | AC35: MTN
A36: 2026-06-08 | B36: gh | C36: 21631392 | D36: 233557444083 | E36: 46082.314 | F36: 289.42 | G36: 0 | H36: 289.42 | I36: 16.05 | J36: 0 | K36: 16.05 | L36: 78 | M36: 1014 | N36: 52.69 | O36: 685 | P36: aviator-user | Q36: [50,1000) | R36: Group A | S36: 0 | T36: 0 | U36: 0 | AB36: 55 | AC36: MTN
A37: 2026-06-08 | B37: gh | C37: 18720280 | D37: 233594085826 | E37: 45929.761 | F37: 510.65 | G37: 0 | H37: 510.65 | I37: 40.21 | J37: 0 | K37: 40.21 | L37: 126.38 | M37: 1643 | N37: 14.23 | O37: 185 | P37: casino-user | Q37: [50,1000) | R37: Group A | S37: 0 | T37: 0 | U37: 0 | AB37: 59 | AC37: MTN
A38: 2026-06-05 | B38: gh | C38: 19498712 | D38: 233201534803 | E38: 45976.899 | F38: 8367.08 | G38: 27.01 | H38: 8340.08 | I38: 151.92 | J38: -0.75 | K38: 152.67 | L38: 1893.92 | M38: 24621 | N38: 919.23 | O38: 11950 | P38: aviator-user | Q38: [1000,10w) | R38: Group A | S38: 0 | T38: 0 | U38: 0 | AB38: 20 | AC38: Telecel
A39: 2026-06-05 | B39: gh | C39: 22491221 | D39: 233204251901 | E39: 46130.449 | F39: 5858.33 | G39: 0.08 | H39: 5858.25 | I39: 178.2 | J39: -0.09 | K39: 178.3 | L39: 904.92 | M39: 11764 | N39: 904.92 | O39: 11764 | P39: aviator-user | Q39: [50,1000) | R39: Group A | S39: 0 | T39: 0 | U39: 0 | AB39: 20 | AC39: Telecel
A40: 2026-06-05 | B40: gh | C40: 20072952 | D40: 233505307892 | E40: 46003.704 | F40: 543.26 | G40: 1.62 | H40: 541.65 | I40: 25.31 | J40: 1.33 | K40: 23.98 | L40: 250.69 | M40: 3259 | N40: 87.85 | O40: 1142 | P40: aviator-user | Q40: [50,1000) | R40: Group A | S40: 0 | T40: 0 | U40: 0 | AB40: 50 | AC40: Telecel
...

Sheet B组
A1: date | B1: country | C1: userid | D1: username | E1: register_time | F1: Total Stake | G1: Total Stake on Sports | H1: Total Stake on Games | I1: Total GGR | J1: Total Sports GGR | K1: Total Gaming GGR | L1: Total Deposit (usd) | M1: Total Deposit (local) | N1: The latest 90days Deposit (usd) | O1: The latest 90days Deposit (local) | P1: User Preference | Q1: deposit_category | R1: label | S1: No-Deposit Sports Coupon(odd>2.5) | T1: casinobonus | U1: VIP-type | V1: sex | W1: first_name | X1: last_name | Y1: birthday | Z1: temp_birthday | AA1: email | AB1: 号段 | AC1: 通讯商
A2: 2026-06-08 | B2: gh | C2: 22400003 | D2: 233201359579 | E2: 46124.903 | F2: 1191.41 | G2: 0 | H2: 1191.41 | I2: 125.54 | J2: -0.14 | K2: 125.67 | L2: 194.08 | M2: 2523 | N2: 194.08 | O2: 2523 | P2: aviator-user | Q2: [50,1000) | R2: Group B | S2: 0 | T2: 126 | U2: 0 | AB2: 20 | AC2: Telecel
A3: 2026-06-08 | B3: gh | C3: 18111154 | D3: 233202159883 | E3: 45892.909 | F3: 729.72 | G3: 0 | H3: 729.72 | I3: 0.93 | J3: 0 | K3: 0.93 | L3: 375.46 | M3: 4881 | N3: 237.77 | O3: 3091 | P3: aviator-user | Q3: [50,1000) | R3: Group B | S3: 0 | T3: 155 | U3: 0 | AB3: 20 | AC3: Telecel
A4: 2026-06-08 | B4: gh | C4: 11300113 | D4: 233202438559 | E4: 45243.507 | F4: 0 | G4: 0 | H4: 0 | I4: 0 | J4: 0 | K4: 0 | L4: 115.38 | M4: 1500 | N4: 0 | O4: 0 | P4: unknown | Q4: [50,1000) | R4: Group B | S4: 120 | T4: 0 | U4: 0 | AB4: 20 | AC4: Telecel
A5: 2026-06-08 | B5: gh | C5: 22786134 | D5: 233500556145 | E5: 46150.523 | F5: 4278.66 | G5: 0 | H5: 4278.66 | I5: 371.61 | J5: 0 | K5: 371.61 | L5: 1015 | M5: 13195 | N5: 1015 | O5: 13195 | P5: aviator-user | Q5: [1000,10w) | R5: Group B | S5: 0 | T5: 660 | U5: 0 | AB5: 50 | AC5: Telecel
A6: 2026-06-08 | B6: gh | C6: 18348573 | D6: 233500580056 | E6: 45906.238 | F6: 3858.05 | G6: 0 | H6: 3858.05 | I6: 73.49 | J6: 0 | K6: 73.49 | L6: 1966.42 | M6: 25563.5 | N6: 874.85 | O6: 11373 | P6: casino-user | Q6: [1000,10w) | R6: Group B | S6: 0 | T6: 569 | U6: 0 | AB6: 50 | AC6: Telecel
A7: 2026-06-08 | B7: gh | C7: 20899433 | D7: 233505126375 | E7: 46043.953 | F7: 378.82 | G7: 0 | H7: 377.43 | I7: 14.05 | J7: 0 | K7: 14.05 | L7: 66.38 | M7: 863 | N7: 51 | O7: 663 | P7: casino-user | Q7: [50,1000) | R7: Group B | S7: 0 | T7: 33 | U7: 0 | AB7: 50 | AC7: Telecel
A8: 2026-06-08 | B8: gh | C8: 21825435 | D8: 233505415114 | E8: 46092.223 | F8: 21584.54 | G8: 0 | H8: 21584.54 | I8: 290.18 | J8: 0 | K8: 290.18 | L8: 2253.85 | M8: 29300 | N8: 2253.85 | O8: 29300 | P8: aviator-user | Q8: [1000,10w) | R8: Group B | S8: 0 | T8: 1465 | U8: 0 | AB8: 50 | AC8: Telecel
A9: 2026-06-08 | B9: gh | C9: 22999645 | D9: 233509066010 | E9: 46165.967 | F9: 305.27 | G9: 0 | H9: 305.27 | I9: 80.77 | J9: 0 | K9: 80.77 | L9: 80.77 | M9: 1050 | N9: 80.77 | O9: 1050 | P9: casino-user | Q9: [50,1000) | R9: Group B | S9: 0 | T9: 52 | U9: 0 | AB9: 50 | AC9: Telecel
A10: 2026-06-08 | B10: gh | C10: 19970315 | D10: 233509875276 | E10: 45999.38 | F10: 173.72 | G10: 29.92 | H10: 143.8 | I10: 44.29 | J10: 24.38 | K10: 19.91 | L10: 82.15 | M10: 1068 | N10: 48.92 | O10: 636 | P10: bet&casino-user | Q10: [50,1000) | R10: Group B | S10: 120 | T10: 16 | U10: 0 | AB10: 50 | AC10: Telecel
A11: 2026-06-08 | B11: gh | C11: 22843754 | D11: 233264612466 | E11: 46155.295 | F11: 8535.52 | G11: 0 | H11: 8535.52 | I11: -287.7 | J11: 0 | K11: -287.7 | L11: 527.69 | M11: 6860 | N11: 527.69 | O11: 6860 | P11: aviator-user | Q11: [50,1000) | R11: Group B | S11: 0 | T11: 343 | U11: 0 | AB11: 26 | AC11: AirtelTigo
A12: 2026-06-08 | B12: gh | C12: 19415225 | D12: 233267635627 | E12: 45973.854 | F12: 177.67 | G12: 99.25 | H12: 78.42 | I12: 62.99 | J12: 47.04 | K12: 15.95 | L12: 127.15 | M12: 1653 | N12: 14.85 | O12: 193 | P12: bet&casino-user | Q12: [50,1000) | R12: Group B | S12: 120 | T12: 5 | U12: 0 | AB12: 26 | AC12: AirtelTigo
A13: 2026-06-08 | B13: gh | C13: 20729693 | D13: 233268228181 | E13: 46035.43 | F13: 7524.73 | G13: 0 | H13: 7524.73 | I13: 464.14 | J13: 0 | K13: 464.14 | L13: 1941.31 | M13: 25237 | N13: 1825.92 | O13: 23737 | P13: aviator-user | Q13: [1000,10w) | R13: Group B | S13: 0 | T13: 1187 | U13: 0 | AB13: 26 | AC13: AirtelTigo
... A33: 2026-06-08 | B33: gh | C33: 19665645 | D33: 233537951485 | E33: 45984.597 | F33: 235.22 | G33: 0 | H33: 235.22 | I33: 19.72 | J33: 0 | K33: 19.72 | L33: 61.77 | M33: 803 | N33: 3.46 | O33: 45 | P33: casino-user | Q33: [50,1000) | R33: Group B | S33: 0 | T33: 2 | U33: 0 | AB33: 53 | AC33: MTN
A34: 2026-06-08 | B34: gh | C34: 19622364 | D34: 233540312088 | E34: 45982.53 | F34: 29300.89 | G34: 27.37 | H34: 29273.52 | I34: -820.64 | J34: 21.49 | K34: -842.13 | L34: 9965.54 | M34: 129552 | N34: 314.15 | O34: 4084 | P34: aviator-user | Q34: [1000,10w) | R34: Group B | S34: 0 | T34: 204 | U34: 1 | V34: 1 | AB34: 54 | AC34: MTN
A35: 2026-06-08 | B35: gh | C35: 22387195 | D35: 233540576978 | E35: 46124.302 | F35: 400 | G35: 0 | H35: 400 | I35: -19.23 | J35: 0 | K35: -19.23 | L35: 138.46 | M35: 1800 | N35: 138.46 | O35: 1800 | P35: casino-user | Q35: [50,1000) | R35: Group B | S35: 0 | T35: 90 | U35: 0 | AB35: 54 | AC35: MTN
A36: 2026-06-08 | B36: gh | C36: 13794514 | D36: 233541576758 | E36: 45556.626 | F36: 4337.2 | G36: 1421.21 | H36: 2915.99 | I36: 599.69 | J36: 426.23 | K36: 173.46 | L36: 1847.46 | M36: 24017 | N36: 208.31 | O36: 2708 | P36: bet&casino-user | Q36: [1000,10w) | R36: Group B | S36: 500 | T36: 68 | U36: 0 | AB36: 54 | AC36: MTN
A37: 2026-06-08 | B37: gh | C37: 20226304 | D37: 233541808237 | E37: 46011.476 | F37: 9914.79 | G37: 78.84 | H37: 9835.96 | I37: 591.32 | J37: -12.47 | K37: 603.79 | L37: 1699.23 | M37: 22090 | N37: 1218.38 | O37: 15839 | P37: aviator-user | Q37: [1000,10w) | R37: Group B | S37: 0 | T37: 792 | U37: 0 | AB37: 54 | AC37: MTN
A38: 2026-06-08 | B38: gh | C38: 18333044 | D38: 233542168939 | E38: 45905.299 | F38: 338.13 | G38: 12 | H38: 326.13 | I38: 9.46 | J38: 0.58 | K38: 8.88 | L38: 81 | M38: 1053 | N38: 0.38 | O38: 5 | P38: aviator-user | Q38: [50,1000) | R38: Group B | S38: 0 | T38: 0 | U38: 0 | AB38: 54 | AC38: MTN
A39: 2026-06-08 | B39: gh | C39: 22889213 | D39: 233543639050 | E39: 46157.723 | F39: 28299.31 | G39: 0 | H39: 28299.31 | I39: 812.66 | J39: 0 | K39: 812.66 | L39: 3254.31 | M39: 42306 | N39: 3254.31 | O39: 42306 | P39: aviator-user | Q39: [1000,10w) | R39: Group B | S39: 0 | T39: 2115 | U39: 0 | AB39: 54 | AC39: MTN
A40: 2026-06-08 | B40: gh | C40: 17383143 | D40: 233548305001 | E40: 45850.779 | F40: 1479.85 | G40: 5.06 | H40: 1474.78 | I40: 105.99 | J40: 5.06 | K40: 100.93 | L40: 164.85 | M40: 2143 | N40: 0 | O40: 0 | P40: casino-user | Q40: [50,1000) | R40: Group B | S40: 0 | T40: 0 | U40: 0 | AB40: 54 | AC40: MTN
A41: 2026-06-08 | B41: gh | C41: 20235395 | D41: 233551286908 | E41: 46012.01 | F41: 847.51 | G41: 1.05 | H41: 846.45 | I41: 134.23 | J41: 1.05 | K41: 133.18 | L41: 195.15 | M41: 2537 | N41: 25 | O41: 325 | P41: aviator-user | Q41: [50,1000) | R41: Group B | S41: 0 | T41: 16 | U41: 0 | AB41: 55 | AC41: MTN
A42: 2026-06-08 | B42: gh | C42: 22748835 | D42: 233552383650 | E42: 46148.627 | F42: 68962.27 | G42: 0 | H42: 68962.27 | I42: 4416.46 | J42: -0.17 | K42: 4416.63 | L42: 4679.31 | M42: 60831 | N42: 4679.31 | O42: 60831 | P42: aviator-user | Q42: [1000,10w) | R42: Group B | S42: 0 | T42: 3042 | U42: 0 | AB42: 55 | AC42: MTN
A43: 2026-06-08 | B43: gh | C43: 22695905 | D43: 233552619671 | E43: 46144.265 | F43: 468.49 | G43: 2.54 | H43: 465.95 | I43: 59.44 | J43: 2.54 | K43: 56.9 | L43: 105.92 | M43: 1377 | N43: 105.92 | O43: 1377 | P43: casino-user | Q43: [50,1000) | R43: Group B | S43: 0 | T43: 69 | U43: 0 | AB43: 55 | AC43: MTN
A44: 2026-06-08 | B44: gh | C44: 14312965 | D44: 233554485255 | E44: 45593.23 | F44: 15309.44 | G44: 3.08 | H44: 15306.37 | I44: 605.49 | J44: 3.08 | K44: 602.41 | L44: 1134.54 | M44: 14749 | N44: 568.15 | O44: 7386 | P44: aviator-user | Q44: [1000,10w) | R44: Group B | S44: 0 | T44: 369 | U44: 0 | AB44: 55 | AC44: MTN
A45: 2026-06-08 | B45: gh | C45: 20505795 | D45: 233554857562 | E45: 46024.81 | F45: 4706.26 | G45: 2.87 | H45: 4703.39 | I45: 158.92 | J45: 2.63 | K45: 156.29 | L45: 597.31 | M45: 7765 | N45: 562.23 | O45: 7309 | P45: aviator-user | Q45: [50,1000) | R45: Group B | S45: 0 | T45: 365 | U45: 0 | AB45: 55 | AC45: MTN
A46: 2026-06-08 | B46: gh | C46: 22613094 | D46: 233555333290 | E46: 46138.512 | F46: 363.16 | G46: 0 | H46: 363.16 | I46: 42.69 | J46: 0 | K46: 42.69 | L46: 58.08 | M46: 755 | N46: 58.08 | O46: 755 | P46: casino-user | Q46: [50,1000) | R46: Group B | S46: 0 | T46: 38 | U46: 0 | AB46: 55 | AC46: MTN
... A60: 2026-06-05 | B60: gh | C60: 3453065 | D60: 233243788708 | E60: 44224.955 | F60: 602.23 | G60: 0 | H60: 602.23 | I60: 131.46 | J60: 0 | K60: 131.46 | L60: 131.46 | M60: 1709 | N60: 2.31 | O60: 30 | P60: casino-user | Q60: [50,1000) | R60: Group B | S60: 0 | T60: 2 | U60: 0 | AB60: 24 | AC60: MTN
A61: 2026-06-05 | B61: gh | C61: 9895703 | D61: 233246773930 | E61: 45051.695 | F61: 133581.67 | G61: 0 | H61: 133581.67 | I61: 1859.76 | J61: 0 | K61: 1859.76 | L61: 33645.31 | M61: 437389 | N61: 6278.54 | O61: 81621 | P61: casino-user | Q61: [1000,10w) | R61: Group B | S61: 0 | T61: 4081 | U61: 1 | V61: 1 | AB61: 24 | AC61: MTN
A62: 2026-06-05 | B62: gh | C62: 22107934 | D62: 233531482687 | E62: 46108.005 | F62: 248.54 | G62: 13.23 | H62: 235.31 | I62: 30.56 | J62: 8.67 | K62: 21.9 | L62: 62 | M62: 806 | N62: 62 | O62: 806 | P62: aviator-user | Q62: [50,1000) | R62: Group B | S62: 0 | T62: 40 | U62: 0 | AB62: 53 | AC62: MTN
A63: 2026-06-05 | B63: gh | C63: 9795303 | D63: 233531894257 | E63: 45034.405 | F63: 321.85 | G63: 69.54 | H63: 252.31 | I63: 17.69 | J63: 64.11 | K63: -46.42 | L63: 320.15 | M63: 4162 | N63: 59.31 | O63: 771 | P63: bet&casino-user | Q63: [50,1000) | R63: Group B | S63: 120 | T63: 19 | U63: 0 | AB63: 53 | AC63: MTN
A64: 2026-06-05 | B64: gh | C64: 18844063 | D64: 233532035600 | E64: 45937.908 | F64: 5483.1 | G64: 19.47 | H64: 5463.62 | I64: 392.92 | J64: 19.47 | K64: 373.44 | L64: 1365.38 | M64: 17750 | N64: 629.62 | O64: 8185 | P64: aviator-user | Q64: [1000,10w) | R64: Group B | S64: 0 | T64: 409 | U64: 0 | AB64: 53 | AC64: MTN
A65: 2026-06-05 | B65: gh | C65: 10684725 | D65: 233532670211 | E65: 45184.595 | F65: 5604.09 | G65: 0.85 | H65: 5603.25 | I65: 181.7 | J65: 0.6 | K65: 181.1 | L65: 586.77 | M65: 7628 | N65: 23.85 | O65: 310 | P65: aviator-user | Q65: [50,1000) | R65: Group B | S65: 0 | T65: 16 | U65: 0 | AB65: 53 | AC65: MTN
A66: 2026-06-05 | B66: gh | C66: 19680015 | D66: 233533549777 | E66: 45985.497 | F66: 279923.95 | G66: 0 | H66: 279923.95 | I66: 1953.76 | J66: -0.18 | K66: 1953.94 | L66: 25464.77 | M66: 331042 | N66: 0 | O66: 0 | P66: aviator-user | Q66: [1000,10w) | R66: Group B | S66: 0 | T66: 0 | U66: 1 | V66: 1 | AB66: 53 | AC66: MTN
A67: 2026-06-05 | B67: gh | C67: 20156004 | D67: 233534036763 | E67: 46007.994 | F67: 943.85 | G67: 3.22 | H67: 937.17 | I67: -17.01 | J67: 3.22 | K67: -20.23 | L67: 229.31 | M67: 2981 | N67: 0 | O67: 0 | P67: aviator-user | Q67: [50,1000) | R67: Group B | S67: 0 | T67: 0 | U67: 0 | AB67: 53 | AC67: MTN
A68: 2026-06-05 | B68: gh | C68: 17738463 | D68: 233536040004 | E68: 45872.597 | F68: 20289.65 | G68: 92.22 | H68: 20197.42 | I68: -332.81 | J68: 53.53 | K68: -386.34 | L68: 3564.15 | M68: 46334 | N68: 3061.85 | O68: 39804 | P68: aviator-user | Q68: [1000,10w) | R68: Group B | S68: 0 | T68: 1990 | U68: 1 | V68: 1 | AB68: 53 | AC68: MTN
A69: 2026-06-05 | B69: gh | C69: 20792863 | D69: 233539595174 | E69: 46038.666 | F69: 37770.59 | G69: 0.23 | H69: 37770.36 | I69: 2300.43 | J69: 0.23 | K69: 2300.2 | L69: 4814.77 | M69: 62592 | N69: 3441.54 | O69: 44740 | P69: aviator-user | Q69: [1000,10w) | R69: Group B | S69: 0 | T69: 2237 | U69: 1 | V69: 1 | AB69: 53 | AC69: MTN
A70: 2026-06-05 | B70: gh | C70: 13052233 | D70: 233539622144 | E70: 45436.583 | F70: 228.82 | G70: 83.46 | H70: 145.35 | I70: 32.85 | J70: 4.31 | K70: 28.54 | L70: 128.08 | M70: 1665 | N70: 3.46 | O70: 45 | P70: bet&casino-user | Q70: [50,1000) | R70: Group B | S70: 120 | T70: 1 | U70: 0 | AB70: 53 | AC70: MTN
A71: 2026-06-05 | B71: gh | C71: 20783243 | D71: 233539965983 | E71: 46038.307 | F71: 820.46 | G71: 8.71 | H71: 811.76 | I71: 35.14 | J71: -9.66 | K71: 44.8 | L71: 84.69 | M71: 1101 | N71: 19.85 | O71: 258 | P71: casino-user | Q71: [50,1000) | R71: Group B | S71: 0 | T71: 13 | U71: 0 | AB71: 53 | AC71: MTN
A72: 2026-06-05 | B72: gh | C72: 17570495 | D72: 233541140331 | E72: 45863.525 | F72: 597 | G72: 1.23 | H72: 595.77 | I72: 36.31 | J72: 1.23 | K72: 35.08 | L72: 139.15 | M72: 1809 | N72: 78 | O72: 1014 | P72: casino-user | Q72: [50,1000) | R72: Group B | S72: 0 | T72: 51 | U72: 0 | AB72: 54 | AC72: MTN
...

Sheet C组
A1: date | B1: country | C1: userid | D1: username | E1: register_time | F1: Total Stake | G1: Total Stake on Sports | H1: Total Stake on Games | I1: Total GGR | J1: Total Sports GGR | K1: Total Gaming GGR | L1: Total Deposit (usd) | M1: Total Deposit (local) | N1: The latest 90days Deposit (usd) | O1: The latest 90days Deposit (local) | P1: User Preference | Q1: deposit_category | R1: label | S1: No-Deposit Sports Coupon(odd>2.5) | T1: casinobonus | U1: VIP-type | V1: sex | W1: first_name | X1: last_name | Y1: birthday | Z1: temp_birthday | AA1: email | AB1: 号段 | AC1: 通讯商
A2: 2026-06-08 | B2: gh | C2: 22965717 | D2: 233200444912 | E2: 46163.618 | F2: 1971.46 | G2: 0 | H2: 1971.46 | I2: 214.54 | J2: 0 | K2: 214.54 | L2: 336.85 | M2: 4379 | N2: 336.85 | O2: 4379 | P2: aviator-user | Q2: [50,1000) | R2: Group C | S2: 0 | T2: 219 | U2: 0 | AB2: 20 | AC2: Telecel
A3: 2026-06-08 | B3: gh | C3: 17022597 | D3: 233502081093 | E3: 45824.501 | F3: 379.19 | G3: 66.51 | H3: 312.68 | I3: 3.83 | J3: -49.3 | K3: 53.13 | L3: 160.15 | M3: 2082 | N3: 97.46 | O3: 1267 | P3: bet&casino-user | Q3: [50,1000) | R3: Group C | S3: 120 | T3: 52 | U3: 0 | AB3: 50 | AC3: Telecel
A4: 2026-06-08 | B4: gh | C4: 21942736 | D4: 233503517522 | E4: 46098.63 | F4: 630.23 | G4: 0 | H4: 630.23 | I4: 237.95 | J4: 0 | K4: 237.95 | L4: 384.62 | M4: 5000 | N4: 384.62 | O4: 5000 | P4: casino-user | Q4: [50,1000) | R4: Group C | S4: 0 | T4: 250 | U4: 0 | AB4: 50 | AC4: Telecel
A5: 2026-06-08 | B5: gh | C5: 21330248 | D5: 233507375778 | E5: 46067.603 | F5: 728.91 | G5: 422.48 | H5: 306.43 | I5: -254.69 | J5: -324.08 | K5: 69.39 | L5: 454 | M5: 5902 | N5: 356.69 | O5: 4637 | P5: bet&casino-user | Q5: [50,1000) | R5: Group C | S5: 120 | T5: 148 | U5: 0 | AB5: 50 | AC5: Telecel
A6: 2026-06-08 | B6: gh | C6: 6990358 | D6: 233270922498 | E6: 44625.425 | F6: 7119.97 | G6: 0.85 | H6: 7119.12 | I6: 311.22 | J6: 0.85 | K6: 310.38 | L6: 865.69 | M6: 11254 | N6: 98.85 | O6: 1285 | P6: casino-user | Q6: [50,1000) | R6: Group C | S6: 0 | T6: 563 | U6: 0 | AB6: 27 | AC6: AirtelTigo
A7: 2026-06-08 | B7: gh | C7: 20414886 | D7: 233279862324 | E7: 46020.778 | F7: 273.27 | G7: 0 | H7: 273.27 | I7: 15.52 | J7: 0 | K7: 15.52 | L7: 70.15 | M7: 912 | N7: 1.54 | O7: 20 | P7: casino-user | Q7: [50,1000) | R7: Group C | S7: 0 | T7: 46 | U7: 0 | AB7: 27 | AC7: AirtelTigo
A8: 2026-06-08 | B8: gh | C8: 22506286 | D8: 233240252836 | E8: 46131.541 | F8: 296.65 | G8: 0 | H8: 296.65 | I8: 18.07 | J8: 0 | K8: 18.07 | L8: 177.08 | M8: 2302 | N8: 177.08 | O8: 2302 | P8: casino-user | Q8: [50,1000) | R8: Group C | S8: 0 | T8: 115 | U8: 0 | AB8: 24 | AC8: MTN
A9: 2026-06-08 | B9: gh | C9: 9587987 | D9: 233244070496 | E9: 44998.778 | F9: 281.35 | G9: 0 | H9: 281.35 | I9: 35.77 | J9: 0 | K9: 35.77 | L9: 66.54 | M9: 865 | N9: 16.15 | O9: 210 | P9: casino-user | Q9: [50,1000) | R9: Group C | S9: 0 | T9: 43 | U9: 0 | AB9: 24 | AC9: MTN
A10: 2026-06-08 | B10: gh | C10: 17414157 | D10: 233246896108 | E10: 45853.048 | F10: 7053 | G10: 0 | H10: 7053 | I10: 184.96 | J10: 0 | K10: 184.96 | L10: 599.15 | M10: 7789 | N10: 129.92 | O10: 1689 | P10: casino-user | Q10: [50,1000) | R10: Group C | S10: 0 | T10: 389 | U10: 0 | AB10: 24 | AC10: MTN
A11: 2026-06-08 | B11: gh | C11: 21012646 | D11: 233247456529 | E11: 46050.612 | F11: 744.2 | G11: 0 | H11: 744.2 | I11: 47.05 | J11: 0 | K11: 47.05 | L11: 267.15 | M11: 3473 | N11: 89.69 | O11: 1166 | P11: casino-user | Q11: [50,1000) | R11: Group C | S11: 0 | T11: 174 | U11: 0 | AB11: 24 | AC11: MTN
A12: 2026-06-08 | B12: gh | C12: 22884327 | D12: 233248896339 | E12: 46157.406 | F12: 132.27 | G12: 0 | H12: 132.27 | I12: 31.89 | J12: 0 | K12: 31.89 | L12: 84.23 | M12: 1095 | N12: 84.23 | O12: 1095 | P12: aviator-user | Q12: [50,1000) | R12: Group C | S12: 0 | T12: 55 | U12: 0 | AB12: 24 | AC12: MTN
A13: 2026-06-08 | B13: gh | C13: 10343166 | D13: 233530602308 | E13: 45138.554 | F13: 1076.85 | G13: 174 | H13: 902.85 | I13: 133.15 | J13: 64.67 | K13: 68.48 | L13: 366.54 | M13: 4765 | N13: 209.08 | O13: 2718 | P13: bet&casino-user | Q13: [50,1000) | R13: Group C | S13: 120 | T13: 119 | U13: 0 | AB13: 53 | AC13: MTN
... A39: 2026-06-08 | B39: gh | C39: 19217737 | D39: 233558069824 | E39: 45961.902 | F39: 428.03 | G39: 4.62 | H39: 422.49 | I39: 21.98 | J39: 4.07 | K39: 17.91 | L39: 80.08 | M39: 1041 | N39: 3.08 | O39: 40 | P39: casino-user | Q39: [50,1000) | R39: Group C | S39: 0 | T39: 52 | U39: 0 | AB39: 55 | AC39: MTN
A40: 2026-06-08 | B40: gh | C40: 22021019 | D40: 233591831636 | E40: 46103.112 | F40: 44803.84 | G40: 0 | H40: 44803.84 | I40: 985.3 | J40: -0.21 | K40: 985.52 | L40: 5958.85 | M40: 77465 | N40: 5958.85 | O40: 77465 | P40: aviator-user | Q40: [1000,10w) | R40: Group C | S40: 0 | T40: 3873 | U40: 1 | V40: 1 | AB40: 59 | AC40: MTN
A41: 2026-06-08 | B41: gh | C41: 22938699 | D41: 233592211220 | E41: 46161.982 | F41: 3295.49 | G41: 0 | H41: 3295.49 | I41: 170.68 | J41: 0 | K41: 170.68 | L41: 329.46 | M41: 4283 | N41: 329.46 | O41: 4283 | P41: aviator-user | Q41: [50,1000) | R41: Group C | S41: 0 | T41: 214 | U41: 0 | AB41: 59 | AC41: MTN
A42: 2026-06-08 | B42: gh | C42: 22160276 | D42: 233593741782 | E42: 46111.454 | F42: 186.91 | G42: 7.11 | H42: 179.8 | I42: 34.54 | J42: 7.11 | K42: 27.43 | L42: 52.69 | M42: 685 | N42: 52.69 | O42: 685 | P42: aviator-user | Q42: [50,1000) | R42: Group C | S42: 0 | T42: 34 | U42: 0 | AB42: 59 | AC42: MTN
A43: 2026-06-08 | B43: gh | C43: 6931167 | D43: 233594503247 | E43: 44619.537 | F43: 2590.97 | G43: 0.23 | H43: 2590.74 | I43: 424.27 | J43: -0.57 | K43: 424.84 | L43: 1476.38 | M43: 19193 | N43: 1376.38 | O43: 17893 | P43: aviator-user | Q43: [1000,10w) | R43: Group C | S43: 0 | T43: 960 | U43: 0 | AB43: 59 | AC43: MTN
A44: 2026-06-08 | B44: gh | C44: 20404189 | D44: 233594589391 | E44: 46020.382 | F44: 1272.85 | G44: 0 | H44: 1272.85 | I44: 87.81 | J44: 0 | K44: 87.81 | L44: 265.15 | M44: 3447 | N44: 100.69 | O44: 1309 | P44: casino-user | Q44: [50,1000) | R44: Group C | S44: 0 | T44: 172 | U44: 0 | AB44: 59 | AC44: MTN
A45: 2026-06-08 | B45: gh | C45: 18440676 | D45: 233597120659 | E45: 45911.871 | F45: 441.39 | G45: 50.18 | H45: 391.2 | I45: 62.38 | J45: 41.27 | K45: 21.11 | L45: 96.08 | M45: 1249 | N45: 20 | O45: 260 | P45: bet&casino-user | Q45: [50,1000) | R45: Group C | S45: 120 | T45: 31 | U45: 0 | AB45: 59 | AC45: MTN
A46: 2026-06-08 | B46: gh | C46: 19998717 | D46: 233597944137 | E46: 46000.715 | F46: 129.21 | G46: 64.09 | H46: 65.12 | I46: 58.18 | J46: 55.11 | K46: 3.07 | L46: 79.38 | M46: 1032 | N46: 9.54 | O46: 124 | P46: bet&casino-user | Q46: [50,1000) | R46: Group C | S46: 120 | T46: 26 | U46: 0 | AB46: 59 | AC46: MTN
A47: 2026-06-05 | B47: gh | C47: 16687596 | D47: 233204901500 | E47: 45792.481 | F47: 1143.79 | G47: 5.69 | H47: 1138.1 | I47: -115.18 | J47: 5.69 | K47: -120.87 | L47: 230.69 | M47: 2999 | N47: 94.23 | O47: 1225 | P47: casino-user | Q47: [50,1000) | R47: Group C | S47: 0 | T47: 150 | U47: 0 | AB47: 20 | AC47: Telecel
A48: 2026-06-05 | B48: gh | C48: 11946799 | D48: 233208926409 | E48: 45298.841 | F48: 1598.84 | G48: 0 | H48: 1598.84 | I48: 176.38 | J48: 0 | K48: 176.38 | L48: 381.15 | M48: 4955 | N48: 166.31 | O48: 2162 | P48: aviator-user | Q48: [50,1000) | R48: Group C | S48: 0 | T48: 248 | U48: 0 | AB48: 20 | AC48: Telecel
A49: 2026-06-05 | B49: gh | C49: 10504058 | D49: 233209168535 | E49: 45162.39 | F49: 2279.03 | G49: 0 | H49: 2279.03 | I49: 450.76 | J49: 0 | K49: 450.76 | L49: 777.69 | M49: 10110 | N49: 777.69 | O49: 10110 | P49: casino-user | Q49: [50,1000) | R49: Group C | S49: 0 | T49: 506 | U49: 0 | AB49: 20 | AC49: Telecel
A50: 2026-06-05 | B50: gh | C50: 14110309 | D50: 233502506084 | E50: 45577.56 | F50: 148.68 | G50: 5.08 | H50: 143.59 | I50: 13.13 | J50: 5.08 | K50: 8.05 | L50: 52.08 | M50: 677 | N50: 24.15 | O50: 314 | P50: casino-user | Q50: [50,1000) | R50: Group C | S50: 0 | T50: 34 | U50: 0 | AB50: 50 | AC50: Telecel
A51: 2026-06-05 | B51: gh | C51: 9598168 | D51: 233505163657 | E51: 45001.521 | F51: 530.04 | G51: 0 | H51: 530.04 | I51: 15.98 | J51: 0 | K51: 15.98 | L51: 103.08 | M51: 1340 | N51: 103.08 | O51: 1340 | P51: casino-user | Q51: [50,1000) | R51: Group C | S51: 0 | T51: 67 | U51: 0 | AB51: 50 | AC51: Telecel
A52: 2026-06-05 | B52: gh | C52: 19402858 | D52: 233240752841 | E52: 45973.317 | F52: 297.74 | G52: 0 | H52: 297.74 | I52: 57.08 | J52: 0 | K52: 57.08 | L52: 64.77 | M52: 842 | N52: 0 | O52: 0 | P52: aviator-user | Q52: [50,1000) | R52: Group C | S52: 0 | T52: 42 | U52: 0 | AB52: 24 | AC52: MTN
... A79: 2026-06-05 | B79: gh | C79: 19543429 | D79: 233547968425 | E79: 45979.283 | F79: 4791.66 | G79: 0 | H79: 4791.66 | I79: 511.28 | J79: 0 | K79: 511.28 | L79: 1694.69 | M79: 22031 | N79: 1269 | O79: 16497 | P79: aviator-user | Q79: [1000,10w) | R79: Group C | S79: 0 | T79: 1102 | U79: 0 | AB79: 54 | AC79: MTN
A80: 2026-06-05 | B80: gh | C80: 21996776 | D80: 233550882322 | E80: 46101.618 | F80: 65324.75 | G80: 0 | H80: 65324.75 | I80: 6143.59 | J80: -0.25 | K80: 6143.84 | L80: 13787.46 | M80: 179237 | N80: 13787.46 | O80: 179237 | P80: aviator-user | Q80: [1000,10w) | R80: Group C | S80: 0 | T80: 5000 | U80: 1 | V80: 1 | AB80: 55 | AC80: MTN
A81: 2026-06-05 | B81: gh | C81: 8079619 | D81: 233551196817 | E81: 44721.037 | F81: 1797.15 | G81: 237.19 | H81: 1559.95 | I81: -55.58 | J81: 60.28 | K81: -115.86 | L81: 1155.69 | M81: 15024 | N81: 551.38 | O81: 7168 | P81: bet&casino-user | Q81: [1000,10w) | R81: Group C | S81: 500 | T81: 376 | U81: 0 | AB81: 55 | AC81: MTN
A82: 2026-06-05 | B82: gh | C82: 22926508 | D82: 233551591706 | E82: 46160.833 | F82: 319.41 | G82: 0 | H82: 319.41 | I82: 94.04 | J82: 0 | K82: 94.04 | L82: 94.23 | M82: 1225 | N82: 94.23 | O82: 1225 | P82: aviator-user | Q82: [50,1000) | R82: Group C | S82: 0 | T82: 61 | U82: 0 | AB82: 55 | AC82: MTN
A83: 2026-06-05 | B83: gh | C83: 21840737 | D83: 233557327139 | E83: 46092.837 | F83: 698.41 | G83: 8.77 | H83: 688.72 | I83: 124.35 | J83: -3.68 | K83: 128.03 | L83: 265 | M83: 3445 | N83: 265 | O83: 3445 | P83: casino-user | Q83: [50,1000) | R83: Group C | S83: 0 | T83: 172 | U83: 0 | AB83: 55 | AC83: MTN
A84: 2026-06-05 | B84: gh | C84: 19727199 | D84: 233559605292 | E84: 45988.088 | F84: 4636.91 | G84: 10.23 | H84: 4626.68 | I84: 143.61 | J84: 10.23 | K84: 133.38 | L84: 299.23 | M84: 3890 | N84: 299.23 | O84: 3890 | P84: aviator-user | Q84: [50,1000) | R84: Group C | S84: 0 | T84: 194 | U84: 0 | AB84: 55 | AC84: MTN
A85: 2026-06-05 | B85: gh | C85: 20998209 | D85: 233591944922 | E85: 46049.705 | F85: 14374.1 | G85: 1.15 | H85: 14372.95 | I85: 449.08 | J85: 1.15 | K85: 447.93 | L85: 3326.08 | M85: 43239 | N85: 2839.46 | O85: 36913 | P85: aviator-user | Q85: [1000,10w) | R85: Group C | S85: 0 | T85: 2162 | U85: 1 | V85: 1 | AB85: 59 | AC85: MTN
A86: 2026-06-05 | B86: gh | C86: 22734199 | D86: 233593497417 | E86: 46147.437 | F86: 1438.62 | G86: 2.08 | H86: 1436.54 | I86: 99.15 | J86: 2.08 | K86: 97.08 | L86: 509.15 | M86: 6619 | N86: 509.15 | O86: 6619 | P86: casino-user | Q86: [50,1000) | R86: Group C | S86: 0 | T86: 331 | U86: 0 | AB86: 59 | AC86: MTN
A87: 2026-06-05 | B87: gh | C87: 20790157 | D87: 233594017894 | E87: 46038.567 | F87: 2413.17 | G87: 0 | H87: 2413.17 | I87: 185.88 | J87: 0 | K87: 185.88 | L87: 324.38 | M87: 4217 | N87: 146.31 | O87: 1902 | P87: casino-user | Q87: [50,1000) | R87: Group C | S87: 0 | T87: 211 | U87: 0 | AB87: 59 | AC87: MTN
A88: 2026-06-05 | B88: gh | C88: 17182599 | D88: 233596777416 | E88: 45836.882 | F88: 28894.21 | G88: 0.08 | H88: 28894.13 | I88: 1302.63 | J88: -0.36 | K88: 1302.99 | L88: 7930.38 | M88: 103095 | N88: 2126.77 | O88: 27648 | P88: casino-user | Q88: [1000,10w) | R88: Group C | S88: 0 | T88: 5000 | U88: 1 | V88: 1 | AB88: 59 | AC88: MTN
A89: 2026-06-05 | B89: gh | C89: 22209506 | D89: 233597491241 | E89: 46114.526 | F89: 1020 | G89: 0 | H89: 1020 | I89: 163.07 | J89: 0 | K89: 163.07 | L89: 296.92 | M89: 3860 | N89: 296.92 | O89: 3860 | P89: aviator-user | Q89: [50,1000) | R89: Group C | S89: 0 | T89: 193 | U89: 0 | AB89: 59 | AC89: MTN
A90: 2026-06-05 | B90: gh | C90: 7832538 | D90: 233597984883 | E90: 44677.354 | F90: 720.55 | G90: 224.74 | H90: 495.81 | I90: 118 | J90: 103.65 | K90: 14.35 | L90: 337.15 | M90: 4383 | N90: 291 | O90: 3783 | P90: bet&casino-user | Q90: [50,1000) | R90: Group C | S90: 120 | T90: 110 | U90: 0 | AB90: 59 | AC90: MTN
A91: 2026-06-05 | B91: gh | C91: 16979056 | D91: 233266742990 | E91: 45820.908 | F91: 466.61 | G91: 0 | H91: 466.61 | I91: 66.34 | J91: 0 | K91: 66.34 | L91: 73.38 | M91: 954 | N91: 14.77 | O91: 192 | P91: aviator-user | Q91: [50,1000) | R91: Group C | S91: 0 | T91: 48 | U91: 0 | AB91: 26 | AC91: AirtelTigo
...

Sheet combinate
A1: username | B1: label
A2: 233200425461 | B2: Group A
A3: 233202423882 | B3: Group A
A4: 233500578321 | B4: Group A
A5: 233503326514 | B5: Group A
A6: 233506502760 | B6: Group A
A7: 233507814734 | B7: Group A
A8: 233240254349 | B8: Group A
A9: 233243952996 | B9: Group A
A10: 233248914647 | B10: Group A
A11: 233256999078 | B11: Group A
A12: 233257286401 | B12: Group A
A13: 233257564352 | B13: Group A
... A591: 233599762914 | B591: Group C

Sheet Sheet2
A1: 计数项:用户手机号 | B1: 是否回归
A2: label | C2: 是 | D2: 总计 | E2: 回归率
A3: Group A | C3: 46 | D3: 169 | E3: =C3/D3 -> 0.27218935
A4: Group B | C4: 60 | D4: 191 | E4: =C4/D4 -> 0.31413613
A5: Group C | C5: 75 | D5: 230 | E5: =C5/D5 -> 0.32608696
A6: 总计 | C6: 181 | D6: 590
A9: 计数项:用户手机号 | B9: 是否有效回归
A10: label | B10: 否 | C10: 是 | D10: 总计 | E10: 漏斗有效 | F10: 有效回归率
A11: Group A | B11: 136 | C11: 33 | D11: 169 | E11: =GETPIVOTDATA("用户手机号",$A$9,"label","Group A","是否有效回归","是")/C3 -> 0.7173913 | F11: =GETPIVOTDATA("用户手机号",$A$9,"label","Group A","是否有效回归","是")/GETPIVOTDATA("用户手机号",$A$9,"label","Group A") -> 0.19526627
A12: Group B | B12: 151 | C12: 40 | D12: 191 | E12: =GETPIVOTDATA("用户手机号",$A$9,"label","Group B","是否有效回归","是")/C4 -> 0.66666667 | F12: =GETPIVOTDATA("用户手机号",$A$9,"label","Group B","是否有效回归","是")/GETPIVOTDATA("用户手机号",$A$9,"label","Group B") -> 0.20942408
A13: Group C | B13: 182 | C13: 48 | D13: 230 | E13: =GETPIVOTDATA("用户手机号",$A$9,"label","Group C","是否有效回归","是")/C5 -> 0.64 | F13: =GETPIVOTDATA("用户手机号",$A$9,"label","Group C","是否有效回归","是")/GETPIVOTDATA("用户手机号",$A$9,"label","Group C") -> 0.20869565
A14: 总计 | B14: 469 | C14: 121 | D14: 590 | E14: =GETPIVOTDATA("用户手机号",$A$9,"是否有效回归","是")/C6 -> 0.66850829 | F14: =GETPIVOTDATA("用户手机号",$A$9,"是否有效回归","是")/GETPIVOTDATA("用户手机号",$A$9) -> 0.20508475
A18: 是否有效回归 | B18: 是
A20: label | B20: 计数项:是否有效回归 | C20: 求和项:总投注流水（本地货币） | D20: 求和项:全部ggr（本地货币） | E20: 求和项:充值金额（本地货币）
A21: Group A | B21: 33 | C21: 292054.56 | D21: 17777.98 | E21: 33036
A22: Group B | B22: 40 | C22: 189823.56 | D22: 10872.53 | E22: 21339
A23: Group C | B23: 48 | C23: 206406.48 | D23: 18201.37 | E23: 39183
A24: 总计 | B24: 121 | C24: 688284.6 | D24: 46851.88 | E24: 93558
C26: =GETPIVOTDATA("求和项:总投注流水（本地货币）",$A$20,"label","Group A")/GETPIVOTDATA("计数项:是否有效回归",$A$20,"label","Group A") -> 8850.1382 | D26: =GETPIVOTDATA("求和项:全部ggr（本地货币）",$A$20,"label","Group A")/GETPIVOTDATA("计数项:是否有效回归",$A$20,"label","Group A") -> 538.72667 | E26: =GETPIVOTDATA("求和项:充值金额（本地货币）",$A$20,"label","Group A")/GETPIVOTDATA("计数项:是否有效回归",$A$20,"label","Group A") -> 1001.0909
C27: =GETPIVOTDATA("求和项:总投注流水（本地货币）",$A$20,"label","Group B")/GETPIVOTDATA("计数项:是否有效回归",$A$20,"label","Group B") -> 4745.589 | D27: =GETPIVOTDATA("求和项:全部ggr（本地货币）",$A$20,"label","Group B")/GETPIVOTDATA("计数项:是否有效回归",$A$20,"label","Group B") -> 271.81325 | E27: =GETPIVOTDATA("求和项:充值金额（本地货币）",$A$20,"label","Group B")/GETPIVOTDATA("计数项:是否有效回归",$A$20,"label","Group B") -> 533.475
C28: =GETPIVOTDATA("求和项:总投注流水（本地货币）",$A$20,"label","Group C")/GETPIVOTDATA("计数项:是否有效回归",$A$20,"label","Group C") -> 4300.135 | D28: =GETPIVOTDATA("求和项:全部ggr（本地货币）",$A$20,"label","Group C")/GETPIVOTDATA("计数项:是否有效回归",$A$20,"label","Group C") -> 379.19521 | E28: =GETPIVOTDATA("求和项:充值金额（本地货币）",$A$20,"label","Group C")/GETPIVOTDATA("计数项:是否有效回归",$A$20,"label","Group C") -> 816.3125
C29: =GETPIVOTDATA("求和项:总投注流水（本地货币）",$A$20)/GETPIVOTDATA("计数项:是否有效回归",$A$20) -> 5688.3025 | D29: =GETPIVOTDATA("求和项:全部ggr（本地货币）",$A$20)/GETPIVOTDATA("计数项:是否有效回归",$A$20) -> 387.20562 | E29: =GETPIVOTDATA("求和项:充值金额（本地货币）",$A$20)/GETPIVOTDATA("计数项:是否有效回归",$A$20) -> 773.20661

Sheet 总表
A1: label | B1: 用户手机号 | C1: 用户id | D1: 最后登录时间 | E1: 是否有效回归 | F1: 总投注流水（usd） | G1: 总投注流水（本地货币） | H1: 体育投注流水（本地货币） | I1: 游戏投注流水（本地货币） | J1: 体育ggr（本地货币） | K1: 游戏ggr（本地货币） | L1: 全部ggr（usd） | M1: 全部ggr（本地货币） | N1: 充值金额（usd） | O1: 充值金额（本地货币） | P1: 提现金额（usd） | Q1: 提现金额（本地货币）
A2: =VLOOKUP(B2,combinate!A:B,2,FALSE) -> Group A | B2: 233558171044 | C2: 3650431 | D2: 46161.648 | E2: 否 | F2: 0 | G2: 0 | H2: 0 | I2: 0 | J2: 0 | K2: 0 | L2: 0 | M2: 0 | N2: 0 | O2: 0 | P2: 0 | Q2: 0
A3: =VLOOKUP(B3,combinate!A:B,2,FALSE) -> Group A | B3: 233545295774 | C3: 5832722 | D3: 46166.017 | E3: 否 | F3: 0 | G3: 0 | H3: 0 | I3: 0 | J3: 0 | K3: 0 | L3: 0 | M3: 0 | N3: 0 | O3: 0 | P3: 0 | Q3: 0
A4: =VLOOKUP(B4,combinate!A:B,2,FALSE) -> Group B | B4: 233248112064 | C4: 7103744 | D4: 46162.686 | E4: 否 | F4: 0 | G4: 0 | H4: 0 | I4: 0 | J4: 0 | K4: 0 | L4: 0 | M4: 0 | N4: 0 | O4: 0 | P4: 0 | Q4: 0
A5: =VLOOKUP(B5,combinate!A:B,2,FALSE) -> Group C | B5: 233505163657 | C5: 9598168 | D5: 46184.394 | E5: 是 | F5: 54.85 | G5: 713 | H5: 0 | I5: 713 | J5: 0 | K5: 126.7 | L5: 9.75 | M5: 126.7 | N5: 4.62 | O5: 60 | P5: 0 | Q5: 0
A6: =VLOOKUP(B6,combinate!A:B,2,FALSE) -> Group C | B6: 233558696996 | C6: 10001207 | D6: 46160.716 | E6: 否 | F6: 0 | G6: 0 | H6: 0 | I6: 0 | J6: 0 | K6: 0 | L6: 0 | M6: 0 | N6: 0 | O6: 0 | P6: 0 | Q6: 0
A7: =VLOOKUP(B7,combinate!A:B,2,FALSE) -> Group C | B7: 233539246450 | C7: 13226456 | D7: 46182.668 | E7: 是 | F7: 7.15 | G7: 92.97 | H7: 0 | I7: 92.97 | J7: 0 | K7: 55.87 | L7: 4.3 | M7: 55.87 | N7: 4.31 | O7: 56 | P7: 0 | Q7: 0
A8: =VLOOKUP(B8,combinate!A:B,2,FALSE) -> Group C | B8: 233536455716 | C8: 16391417 | D8: 46161.925 | E8: 否 | F8: 0 | G8: 0 | H8: 0 | I8: 0 | J8: 0 | K8: 0 | L8: 0 | M8: 0 | N8: 0 | O8: 0 | P8: 0 | Q8: 0
A9: =VLOOKUP(B9,combinate!A:B,2,FALSE) -> Group C | B9: 233596777416 | C9: 17182599 | D9: 46182.27 | E9: 是 | F9: 139.95 | G9: 1819.3 | H9: 0 | I9: 1819.3 | J9: 0 | K9: 284.85 | L9: 21.91 | M9: 284.85 | N9: 51.92 | O9: 675 | P9: 30 | Q9: 390
A10: =VLOOKUP(B10,combinate!A:B,2,FALSE) -> Group A | B10: 233504756403 | C10: 17523041 | D10: 46184.017 | E10: 否 | F10: 0 | G10: 0 | H10: 0 | I10: 0 | J10: 0 | K10: 0 | L10: 0 | M10: 0 | N10: 0 | O10: 0 | P10: 0 | Q10: 0
A11: =VLOOKUP(B11,combinate!A:B,2,FALSE) -> Group C | B11: 233206082502 | C11: 18173108 | D11: 46183.781 | E11: 否 | F11: 0 | G11: 0 | H11: 0 | I11: 0 | J11: 0 | K11: 0 | L11: 0 | M11: 0 | N11: 0 | O11: 0 | P11: 0 | Q11: 0
A12: =VLOOKUP(B12,combinate!A:B,2,FALSE) -> Group C | B12: 233540982751 | C12: 18685406 | D12: 46166.502 | E12: 否 | F12: 0 | G12: 0 | H12: 0 | I12: 0 | J12: 0 | K12: 0 | L12: 0 | M12: 0 | N12: 0 | O12: 0 | P12: 0 | Q12: 0
A13: =VLOOKUP(B13,combinate!A:B,2,FALSE) -> Group A | B13: 233545807815 | C13: 19569981 | D13: 46183.636 | E13: 是 | F13: 103.15 | G13: 1340.9 | H13: 0 | I13: 1340.9 | J13: 0 | K13: 349.66 | L13: 26.9 | M13: 349.66 | N13: 26.92 | O13: 350 | P13: 0 | Q13: 0
... A591: =VLOOKUP(B591,combinate!A:B,2,FALSE) -> Group B | B591: 233268228181 | C591: 20729693 | D591: 46166.013 | E591: 否 | F591: 0 | G591: 0 | H591: 0 | I591: 0 | J591: 0 | K591: 0 | L591: 0 | M591: 0 | N591: 0 | O591: 0 | P591: 0 | Q591: 0
