Workbook

Sheet A
A1: date | B1: country | C1: userid | D1: username | E1: register_time | F1: Total Stake | G1: Total Stake on Sports | H1: Total Stake on Games | I1: Total GGR | J1: Total Sports GGR | K1: Total Gaming GGR | L1: Total Deposit (usd) | M1: Total Deposit (local) | N1: The latest 90days Deposit (usd) | O1: The latest 90days Deposit (local) | P1: User Preference | Q1: deposit_category | R1: label | S1: No-Deposit Sports Coupon(odd>2.5) | T1: casinobonus | U1: VIP-type | V1: sex | W1: first_name | X1: last_name | Y1: birthday | Z1: temp_birthday | AA1: email
A2: 2026-06-02 | B2: ke | C2: 15642980 | D2: 254115464651 | E2: 45686.858 | F2: 305.99 | G2: 0.64 | H2: 305.35 | I2: 44 | J2: 0.64 | K2: 43.36 | L2: 171.61 | M2: 22824 | N2: 0 | O2: 0 | P2: aviator-user | Q2: [50,1000) | R2: A组 | S2: 0 | T2: 0 | U2: 0
A3: 2026-06-02 | B3: ke | C3: 22090260 | D3: 254116255629 | E3: 46107.19 | F3: 547.32 | G3: 0 | H3: 547.32 | I3: 2.33 | J3: 0 | K3: 2.33 | L3: 78.57 | M3: 10450 | N3: 74.64 | O3: 9927.12 | P3: aviator-user | Q3: [50,1000) | R3: A组 | S3: 0 | T3: 0 | U3: 0
A4: 2026-06-02 | B4: ke | C4: 18902240 | D4: 254116611542 | E4: 45941.496 | F4: 21706.07 | G4: 0.01 | H4: 21706.06 | I4: 1695.64 | J4: 0.01 | K4: 1695.64 | L4: 3937.71 | M4: 523715 | N4: 627.16 | O4: 83412.28 | P4: aviator-user | Q4: [1000,10w) | R4: A组 | S4: 0 | T4: 0 | U4: 1 | V4: 1
A5: 2026-06-02 | B5: ke | C5: 21777972 | D5: 254140047631 | E5: 46089.678 | F5: 2928.16 | G5: 0 | H5: 2928.16 | I5: -24.94 | J5: 0 | K5: -24.94 | L5: 202.47 | M5: 26929 | N5: 192.35 | O5: 25582.55 | P5: aviator-user | Q5: [50,1000) | R5: A组 | S5: 0 | T5: 0 | U5: 0
A6: 2026-06-02 | B6: ke | C6: 22920322 | D6: 254140414468 | E6: 46160.358 | F6: 1.5 | G6: 0 | H6: 1.5 | I6: 1.5 | J6: 0 | K6: 1.5 | L6: 326.09 | M6: 43370 | N6: 309.79 | O6: 41202.07 | P6: aviator-user | Q6: [50,1000) | R6: A组 | S6: 0 | T6: 0 | U6: 0
A7: 2026-06-02 | B7: ke | C7: 22818880 | D7: 254141464090 | E7: 46153.061 | F7: 994.79 | G7: 0 | H7: 994.79 | I7: 14.96 | J7: 0 | K7: 14.96 | L7: 264.46 | M7: 35173 | N7: 251.24 | O7: 33414.92 | P7: aviator-user | Q7: [50,1000) | R7: A组 | S7: 0 | T7: 0 | U7: 0
A8: 2026-06-02 | B8: ke | C8: 11675230 | D8: 254700785323 | E8: 45273.447 | F8: 177.2 | G8: 0 | H8: 177.2 | I8: 18.82 | J8: 0 | K8: 18.82 | L8: 74.11 | M8: 9856 | N8: 1.81 | O8: 240.73 | P8: aviator-user | Q8: [50,1000) | R8: A组 | S8: 0 | T8: 0 | U8: 0
A9: 2026-06-02 | B9: ke | C9: 12450521 | D9: 254703325859 | E9: 45361.062 | F9: 971.38 | G9: 0 | H9: 971.38 | I9: 69.88 | J9: 0 | K9: 69.88 | L9: 89.4 | M9: 11890 | N9: 20.25 | O9: 2693.25 | P9: aviator-user | Q9: [50,1000) | R9: A组 | S9: 0 | T9: 0 | U9: 0
A10: 2026-06-02 | B10: ke | C10: 8093860 | D10: 254703581163 | E10: 44723.818 | F10: 3944.05 | G10: 0.04 | H10: 3944.02 | I10: 214.33 | J10: 0.04 | K10: 214.29 | L10: 447.96 | M10: 59579 | N10: 0 | O10: 0 | P10: casino-user | Q10: [50,1000) | R10: A组 | S10: 0 | T10: 0 | U10: 0
A11: 2026-06-02 | B11: ke | C11: 21941060 | D11: 254707025433 | E11: 46098.55 | F11: 880.3 | G11: 0 | H11: 880.3 | I11: 12.97 | J11: 0 | K11: 12.97 | L11: 51.09 | M11: 6795 | N11: 97.07 | O11: 12910.31 | P11: aviator-user | Q11: [50,1000) | R11: A组 | S11: 0 | T11: 0 | U11: 0
A12: 2026-06-02 | B12: ke | C12: 3021851 | D12: 254707829195 | E12: 44132.584 | F12: 1139.86 | G12: 0.76 | H12: 1139.1 | I12: 130.88 | J12: 0.5 | K12: 131.13 | L12: 342.45 | M12: 45546 | N12: 28.07 | O12: 3733.31 | P12: casino-user | Q12: [50,1000) | R12: A组 | S12: 0 | T12: 0 | U12: 0
A13: 2026-06-02 | B13: ke | C13: 15251970 | D13: 254710659278 | E13: 45657.349 | F13: 565.21 | G13: 0.9 | H13: 563.18 | I13: 73.49 | J13: 0.9 | K13: 72.59 | L13: 86.1 | M13: 11451 | N13: 68.71 | O13: 9138.43 | P13: casino-user | Q13: [50,1000) | R13: A组 | S13: 0 | T13: 0 | U13: 0
A14: 2026-06-02 | B14: ke | C14: 17453882 | D14: 254712366285 | E14: 45856.344 | F14: 23141.11 | G14: 0 | H14: 23141.11 | I14: 301.26 | J14: 0 | K14: 301.26 | L14: 3194.11 | M14: 424817 | N14: 241.43 | O14: 32110.19 | P14: aviator-user | Q14: [1000,10w) | R14: A组 | S14: 0 | T14: 0 | U14: 0
A15: 2026-06-02 | B15: ke | C15: 19874242 | D15: 254712666371 | E15: 45994.931 | F15: 435.15 | G15: 0 | H15: 435.15 | I15: 18.06 | J15: 0 | K15: 18.06 | L15: 149.07 | M15: 19826 | N15: 53.29 | O15: 7087.57 | P15: aviator-user | Q15: [50,1000) | R15: A组 | S15: 0 | T15: 0 | U15: 0
A16: 2026-06-02 | B16: ke | C16: 17833170 | D16: 254712671248 | E16: 45877.606 | F16: 291.34 | G16: 0.21 | H16: 291.13 | I16: 123.02 | J16: 0.21 | K16: 122.8 | L16: 129.55 | M16: 17230 | N16: 123.07 | O16: 16368.31 | P16: aviator-user | Q16: [50,1000) | R16: A组 | S16: 0 | T16: 0 | U16: 0
... A25: 2026-06-02 | B25: ke | C25: 22076041 | D25: 254718571705 | E25: 46106.342 | F25: 5432.94 | G25: 0 | H25: 5432.94 | I25: -22.58 | J25: 0 | K25: -22.58 | L25: 385.34 | M25: 51250 | N25: 732.14 | O25: 97374.62 | P25: aviator-user | Q25: [50,1000) | R25: A组 | S25: 0 | T25: 0 | U25: 0
A26: 2026-06-02 | B26: ke | C26: 86150 | D26: 254718873432 | E26: 43869.414 | F26: 201439.51 | G26: 57.16 | H26: 201382.35 | I26: 2408.51 | J26: 14.91 | K26: 2393.59 | L26: 35000.12 | M26: 4655016 | N26: 2453.74 | O26: 326347.42 | P26: casino-user | Q26: [1000,10w) | R26: A组 | S26: 0 | T26: 0 | U26: 1 | V26: 1
A27: 2026-06-02 | B27: ke | C27: 433962 | D27: 254719211217 | E27: 43919.432 | F27: 269.4 | G27: 0.01 | H27: 269.39 | I27: 48.57 | J27: 0.01 | K27: 48.57 | L27: 102.66 | M27: 13654 | N27: 0 | O27: 0 | P27: casino-user | Q27: [50,1000) | R27: A组 | S27: 0 | T27: 0 | U27: 0
A28: 2026-06-02 | B28: ke | C28: 7890230 | D28: 254722484393 | E28: 44685.732 | F28: 277.17 | G28: 19.62 | H28: 257.55 | I28: -13.89 | J28: -18.98 | K28: 5.85 | L28: 58.29 | M28: 7752 | N28: 44.66 | O28: 5939.78 | P28: aviator-user | Q28: [50,1000) | R28: A组 | S28: 0 | T28: 0 | U28: 0
A29: 2026-06-02 | B29: ke | C29: 8075822 | D29: 254722520329 | E29: 44720.309 | F29: 7478.73 | G29: 87.22 | H29: 7391.51 | I29: 268.24 | J29: 77.78 | K29: 190.46 | L29: 451.68 | M29: 60074 | N29: 0 | O29: 0 | P29: casino-user | Q29: [50,1000) | R29: A组 | S29: 0 | T29: 0 | U29: 0
A30: 2026-06-02 | B30: ke | C30: 13831930 | D30: 254722896574 | E30: 45560.707 | F30: 1438.72 | G30: 0 | H30: 1438.72 | I30: 239.77 | J30: 0 | K30: 239.77 | L30: 371.12 | M30: 49359 | N30: 0 | O30: 0 | P30: casino-user | Q30: [50,1000) | R30: A组 | S30: 0 | T30: 0 | U30: 0
A31: 2026-06-02 | B31: ke | C31: 4979980 | D31: 254723936569 | E31: 44380.607 | F31: 2976.11 | G31: 0.04 | H31: 2976.07 | I31: 108.66 | J31: 0.04 | K31: 108.63 | L31: 453.08 | M31: 60260 | N31: 0 | O31: 0 | P31: casino-user | Q31: [50,1000) | R31: A组 | S31: 0 | T31: 0 | U31: 0
A32: 2026-06-02 | B32: ke | C32: 12171341 | D32: 254725227759 | E32: 45318.534 | F32: 9806.87 | G32: 0.01 | H32: 9806.87 | I32: -119.58 | J32: 0.01 | K32: -119.59 | L32: 1381.2 | M32: 183700 | N32: 107.14 | O32: 14249.62 | P32: aviator-user | Q32: [1000,10w) | R32: A组 | S32: 0 | T32: 0 | U32: 0
A33: 2026-06-02 | B33: ke | C33: 12051141 | D33: 254725327057 | E33: 45307.801 | F33: 403.76 | G33: 0 | H33: 403.76 | I33: 212.1 | J33: 0 | K33: 212.1 | L33: 236.68 | M33: 31479 | N33: 14.29 | O33: 1900.57 | P33: aviator-user | Q33: [50,1000) | R33: A组 | S33: 0 | T33: 0 | U33: 0
A34: 2026-06-02 | B34: ke | C34: 16230890 | D34: 254726479727 | E34: 45760.644 | F34: 322.68 | G34: 0 | H34: 322.68 | I34: 36.34 | J34: 0 | K34: 36.34 | L34: 85.85 | M34: 11418 | N34: 81.23 | O34: 10803.59 | P34: aviator-user | Q34: [50,1000) | R34: A组 | S34: 0 | T34: 0 | U34: 0
A35: 2026-06-02 | B35: ke | C35: 3908470 | D35: 254726552750 | E35: 44278.436 | F35: 967.55 | G35: 0.23 | H35: 967.32 | I35: 120.47 | J35: 0.23 | K35: 120.99 | L35: 260.55 | M35: 34653 | N35: 0 | O35: 0 | P35: casino-user | Q35: [50,1000) | R35: A组 | S35: 0 | T35: 0 | U35: 0
A36: 2026-06-02 | B36: ke | C36: 21745740 | D36: 254726713819 | E36: 46087.998 | F36: 401.02 | G36: 0 | H36: 401.02 | I36: -71.83 | J36: 0 | K36: -71.83 | L36: 89.31 | M36: 11878 | N36: 84.84 | O36: 11283.72 | P36: casino-user | Q36: [50,1000) | R36: A组 | S36: 0 | T36: 0 | U36: 0
A37: 2026-06-02 | B37: ke | C37: 16787552 | D37: 254729060989 | E37: 45802.858 | F37: 35399.22 | G37: 4.26 | H37: 35394.97 | I37: 1370.06 | J37: 4.26 | K37: 1365.8 | L37: 2381.45 | M37: 316733 | N37: 2826 | O37: 375858 | P37: casino-user | Q37: [1000,10w) | R37: A组 | S37: 0 | T37: 0 | U37: 0
A38: 2026-06-02 | B38: ke | C38: 8736450 | D38: 254740659395 | E38: 44822.873 | F38: 17855.71 | G38: 1.77 | H38: 17853.94 | I38: 756.78 | J38: 1.77 | K38: 755.01 | L38: 1995.02 | M38: 265337 | N38: 109.91 | O38: 14618.03 | P38: casino-user | Q38: [1000,10w) | R38: A组 | S38: 0 | T38: 0 | U38: 0
... A58: 2026-06-02 | B58: ke | C58: 20679651 | D58: 254796811544 | E58: 46032.841 | F58: 8199.47 | G58: 0 | H58: 8199.47 | I58: 630.3 | J58: 0 | K58: 630.3 | L58: 2183.16 | M58: 290360 | N58: 1325.19 | O58: 176250.27 | P58: aviator-user | Q58: [1000,10w) | R58: A组 | S58: 0 | T58: 0 | U58: 0
A59: 2026-06-03 | B59: ke | C59: 8786540 | D59: 254115340046 | E59: 44833.174 | F59: 6185.22 | G59: 3.75 | H59: 6181.46 | I59: -55.13 | J59: 3.75 | K59: -58.88 | L59: 1580.49 | M59: 210205 | N59: 24.37 | O59: 3241.21 | P59: casino-user | Q59: [1000,10w) | R59: Group A | S59: 0 | T59: 0 | U59: 0
A60: 2026-06-03 | B60: ke | C60: 18838120 | D60: 254116176707 | E60: 45937.532 | F60: 330.93 | G60: 0.1 | H60: 330.83 | I60: 15.62 | J60: -0.22 | K60: 15.84 | L60: 70.53 | M60: 9381 | N60: 67.01 | O60: 8912.33 | P60: aviator-user | Q60: [50,1000) | R60: Group A | S60: 0 | T60: 0 | U60: 0
A61: 2026-06-03 | B61: ke | C61: 20667840 | D61: 254117536106 | E61: 46032.413 | F61: 2441.78 | G61: 0.14 | H61: 2441.65 | I61: 207.81 | J61: 0.14 | K61: 207.68 | L61: 341.47 | M61: 45415 | N61: 264.04 | O61: 35117.32 | P61: casino-user | Q61: [50,1000) | R61: Group A | S61: 0 | T61: 0 | U61: 0
A62: 2026-06-03 | B62: ke | C62: 22263010 | D62: 254118389347 | E62: 46117.598 | F62: 515.15 | G62: 0 | H62: 515.15 | I62: 50.53 | J62: 0 | K62: 50.53 | L62: 109.74 | M62: 14595 | N62: 104.25 | O62: 13865.25 | P62: aviator-user | Q62: [50,1000) | R62: Group A | S62: 0 | T62: 0 | U62: 0
A63: 2026-06-03 | B63: ke | C63: 20967302 | D63: 254119659526 | E63: 46047.695 | F63: 1586.22 | G63: 0 | H63: 1586.22 | I63: 98.33 | J63: -0.24 | K63: 98.57 | L63: 103.51 | M63: 13767 | N63: 50.98 | O63: 6780.34 | P63: casino-user | Q63: [50,1000) | R63: Group A | S63: 0 | T63: 0 | U63: 0
A64: 2026-06-03 | B64: ke | C64: 20089772 | D64: 254700688912 | E64: 46004.62 | F64: 1836.36 | G64: 0 | H64: 1836.36 | I64: 147.32 | J64: 0 | K64: 147.32 | L64: 437.11 | M64: 58135 | N64: 414.29 | O64: 55100.57 | P64: aviator-user | Q64: [50,1000) | R64: Group A | S64: 0 | T64: 0 | U64: 0
A65: 2026-06-03 | B65: ke | C65: 11930770 | D65: 254702569649 | E65: 45297.537 | F65: 232.91 | G65: 0 | H65: 232.91 | I65: 42.06 | J65: 0 | K65: 42.06 | L65: 83.41 | M65: 11094 | N65: 51.4 | O65: 6836.2 | P65: casino-user | Q65: [50,1000) | R65: Group A | S65: 0 | T65: 0 | U65: 0
A66: 2026-06-03 | B66: ke | C66: 4819872 | D66: 254704021138 | E66: 44367.329 | F66: 336.43 | G66: 0 | H66: 336.43 | I66: 31.4 | J66: 0 | K66: 31.4 | L66: 100.24 | M66: 13332 | N66: 0 | O66: 0 | P66: casino-user | Q66: [50,1000) | R66: Group A | S66: 0 | T66: 0 | U66: 0
A67: 2026-06-03 | B67: ke | C67: 22174682 | D67: 254704177773 | E67: 46112.382 | F67: 1015.07 | G67: 1.2 | H67: 1013.87 | I67: 60.7 | J67: -0.03 | K67: 60.73 | L67: 105.45 | M67: 14025 | N67: 100.18 | O67: 13323.94 | P67: casino-user | Q67: [50,1000) | R67: Group A | S67: 0 | T67: 0 | U67: 0
...

Sheet B
A1: date | B1: country | C1: userid | D1: username | E1: register_time | F1: Total Stake | G1: Total Stake on Sports | H1: Total Stake on Games | I1: Total GGR | J1: Total Sports GGR | K1: Total Gaming GGR | L1: Total Deposit (usd) | M1: Total Deposit (local) | N1: The latest 90days Deposit (usd) | O1: The latest 90days Deposit (local) | P1: User Preference | Q1: deposit_category | R1: label | S1: No-Deposit Sports Coupon(odd>2.5) | T1: casinobonus | U1: VIP-type | V1: sex | W1: first_name | X1: last_name | Y1: birthday | Z1: temp_birthday | AA1: email
A2: 2026-06-02 | B2: ke | C2: 19009964 | D2: 254112794842 | E2: 45948.696 | F2: 523.05 | G2: 6.38 | H2: 516.67 | I2: 33.5 | J2: -5.66 | K2: 39.16 | L2: 67.86 | M2: 9026 | N2: 20.89 | O2: 2778.37 | P2: aviator-user | Q2: [50,1000) | R2: B组 | S2: 0 | T2: 140 | U2: 0
A3: 2026-06-02 | B3: ke | C3: 18640454 | D3: 254112879367 | E3: 45924.72 | F3: 2008.94 | G3: 0 | H3: 2008.94 | I3: 69.79 | J3: 0 | K3: 69.79 | L3: 273.68 | M3: 36400 | N3: 4.29 | O3: 570.57 | P3: casino-user | Q3: [50,1000) | R3: B组 | S3: 0 | T3: 30 | U3: 0
A4: 2026-06-02 | B4: ke | C4: 20109073 | D4: 254116873056 | E4: 46005.621 | F4: 299.32 | G4: 0 | H4: 299.32 | I4: 36.91 | J4: 0 | K4: 36.91 | L4: 59.09 | M4: 7859 | N4: 18.93 | O4: 2517.69 | P4: aviator-user | Q4: [50,1000) | R4: B组 | S4: 0 | T4: 130 | U4: 0
A5: 2026-06-02 | B5: ke | C5: 15153514 | D5: 254117218951 | E5: 45649.784 | F5: 1516.06 | G5: 0 | H5: 1516.06 | I5: 106.41 | J5: 0 | K5: 106.41 | L5: 744.7 | M5: 99045 | N5: 82.15 | O5: 10925.95 | P5: aviator-user | Q5: [50,1000) | R5: B组 | S5: 0 | T5: 550 | U5: 0
A6: 2026-06-02 | B6: ke | C6: 22438443 | D6: 254119811061 | E6: 46127.51 | F6: 209.92 | G6: 1.2 | H6: 208.71 | I6: 20.99 | J6: 1.2 | K6: 19.78 | L6: 52.74 | M6: 7015 | N6: 50.11 | O6: 6664.63 | P6: aviator-user | Q6: [50,1000) | R6: B组 | S6: 0 | T6: 330 | U6: 0
A7: 2026-06-02 | B7: ke | C7: 21690193 | D7: 254140232432 | E7: 46085.247 | F7: 258.35 | G7: 0 | H7: 258.35 | I7: 20.65 | J7: 0 | K7: 20.65 | L7: 85.2 | M7: 11332 | N7: 80.94 | O7: 10765.02 | P7: aviator-user | Q7: [50,1000) | R7: B组 | S7: 0 | T7: 540 | U7: 0
A8: 2026-06-02 | B8: ke | C8: 22354975 | D8: 254140928434 | E8: 46122.367 | F8: 1172.23 | G8: 0.67 | H8: 1171.56 | I8: 2.72 | J8: -0.14 | K8: 2.86 | L8: 104.45 | M8: 13892 | N8: 198.46 | O8: 26395.18 | P8: aviator-user | Q8: [50,1000) | R8: B组 | S8: 0 | T8: 1320 | U8: 0
A9: 2026-06-02 | B9: ke | C9: 22592073 | D9: 254700099870 | E9: 46136.803 | F9: 180.78 | G9: 0 | H9: 180.78 | I9: -25.91 | J9: 0 | K9: -25.91 | L9: 80.68 | M9: 10730 | N9: 76.64 | O9: 10193.12 | P9: aviator-user | Q9: [50,1000) | R9: B组 | S9: 0 | T9: 510 | U9: 0
A10: 2026-06-02 | B10: ke | C10: 17674564 | D10: 254701925448 | E10: 45869.615 | F10: 726.49 | G10: 2.89 | H10: 723.61 | I10: 17.88 | J10: 0.3 | K10: 17.58 | L10: 140.53 | M10: 18691 | N10: 19.16 | O10: 2548.28 | P10: aviator-user | Q10: [50,1000) | R10: B组 | S10: 0 | T10: 130 | U10: 0
A11: 2026-06-02 | B11: ke | C11: 201673 | D11: 254702551241 | E11: 43918.399 | F11: 770.22 | G11: 0 | H11: 770.22 | I11: 42.95 | J11: 0 | K11: 42.95 | L11: 83.14 | M11: 11057 | N11: 14.29 | O11: 1900.57 | P11: casino-user | Q11: [50,1000) | R11: B组 | S11: 0 | T11: 100 | U11: 0
A12: 2026-06-02 | B12: ke | C12: 15895264 | D12: 254705881860 | E12: 45710.338 | F12: 1686.21 | G12: 0 | H12: 1686.21 | I12: 101.49 | J12: 0 | K12: 101.49 | L12: 176 | M12: 23408 | N12: 62.4 | O12: 8299.2 | P12: aviator-user | Q12: [50,1000) | R12: B组 | S12: 0 | T12: 410 | U12: 0
A13: 2026-06-02 | B13: ke | C13: 4084425 | D13: 254706721015 | E13: 44293.336 | F13: 466.54 | G13: 0 | H13: 466.54 | I13: 54.71 | J13: 0 | K13: 54.71 | L13: 57.59 | M13: 7660 | N13: 54.71 | O13: 7276.43 | P13: aviator-user | Q13: [50,1000) | R13: B组 | S13: 0 | T13: 360 | U13: 0
... A27: 2026-06-02 | B27: ke | C27: 16944543 | D27: 254720986570 | E27: 45817.89 | F27: 96.96 | G27: 63.26 | H27: 33.7 | I27: 54.14 | J27: 48.05 | K27: 6.09 | L27: 61.4 | M27: 8166 | N27: 5.94 | O27: 790.02 | P27: bet&casino-user | Q27: [50,1000) | R27: B组 | S27: 2000 | T27: 20 | U27: 0
A28: 2026-06-02 | B28: ke | C28: 13348445 | D28: 254721973796 | E28: 45493.786 | F28: 34555.36 | G28: 0 | H28: 34555.36 | I28: 1377.58 | J28: 0 | K28: 1377.58 | L28: 5317.68 | M28: 707252 | N28: 695.49 | O28: 92500.17 | P28: aviator-user | Q28: [1000,10w) | R28: B组 | S28: 0 | T28: 4630 | U28: 1 | V28: 1
A29: 2026-06-02 | B29: ke | C29: 1905083 | D29: 254722570452 | E29: 44030.459 | F29: 190.04 | G29: 10.6 | H29: 179.44 | I29: 11.55 | J29: 8.35 | K29: 3.21 | L29: 75.04 | M29: 9980 | N29: 30.29 | O29: 4028.57 | P29: aviator-user | Q29: [50,1000) | R29: B组 | S29: 0 | T29: 200 | U29: 0
A30: 2026-06-02 | B30: ke | C30: 12050133 | D30: 254722811615 | E30: 45307.737 | F30: 2094.23 | G30: 0.08 | H30: 2094.15 | I30: 100.75 | J30: 0.08 | K30: 100.66 | L30: 321.06 | M30: 42701 | N30: 220.39 | O30: 29311.87 | P30: aviator-user | Q30: [50,1000) | R30: B组 | S30: 0 | T30: 1470 | U30: 0
A31: 2026-06-02 | B31: ke | C31: 6267145 | D31: 254723768567 | E31: 44552.291 | F31: 357.71 | G31: 0.09 | H31: 357.62 | I31: 58.76 | J31: 0.09 | K31: 59.42 | L31: 67.56 | M31: 8986 | N31: 31.86 | O31: 4237.38 | P31: casino-user | Q31: [50,1000) | R31: B组 | S31: 0 | T31: 210 | U31: 0
A32: 2026-06-02 | B32: ke | C32: 12289694 | D32: 254723978682 | E32: 45333.737 | F32: 189.88 | G32: 0 | H32: 189.88 | I32: 2.61 | J32: 0 | K32: 2.61 | L32: 76.66 | M32: 10196 | N32: 0 | O32: 0 | P32: aviator-user | Q32: [50,1000) | R32: B组 | S32: 0 | T32: 0 | U32: 0
A33: 2026-06-02 | B33: ke | C33: 19462453 | D33: 254724121209 | E33: 45975.642 | F33: 281.17 | G33: 3.02 | H33: 278.15 | I33: 4.36 | J33: 2.55 | K33: 1.82 | L33: 60.32 | M33: 8023 | N33: 35.45 | O33: 4714.85 | P33: casino-user | Q33: [50,1000) | R33: B组 | S33: 0 | T33: 240 | U33: 0
A34: 2026-06-02 | B34: ke | C34: 16840454 | D34: 254724864149 | E34: 45808.581 | F34: 1955.49 | G34: 0 | H34: 1955.49 | I34: 92.9 | J34: 0 | K34: 92.9 | L34: 167.51 | M34: 22279 | N34: 147.07 | O34: 19560.31 | P34: aviator-user | Q34: [50,1000) | R34: B组 | S34: 0 | T34: 980 | U34: 0
A35: 2026-06-02 | B35: ke | C35: 21178694 | D35: 254728784586 | E35: 46059.563 | F35: 342.26 | G35: 0 | H35: 342.26 | I35: 62.5 | J35: 0 | K35: 62.5 | L35: 65.83 | M35: 8755 | N35: 110.79 | O35: 14735.07 | P35: casino-user | Q35: [50,1000) | R35: B组 | S35: 0 | T35: 740 | U35: 0
A36: 2026-06-02 | B36: ke | C36: 11507753 | D36: 254729703345 | E36: 45258.252 | F36: 3603.28 | G36: 2.58 | H36: 3600.7 | I36: 5.16 | J36: 2.58 | K36: 2.58 | L36: 317.89 | M36: 42280 | N36: 117 | O36: 15561 | P36: aviator-user | Q36: [50,1000) | R36: B组 | S36: 0 | T36: 780 | U36: 0
A37: 2026-06-02 | B37: ke | C37: 3519405 | D37: 254729879984 | E37: 44239.82 | F37: 5177.25 | G37: 0.23 | H37: 5177.02 | I37: 390.5 | J37: -7.39 | K37: 397.88 | L37: 398.12 | M37: 52950 | N37: 0 | O37: 0 | P37: casino-user | Q37: [50,1000) | R37: B组 | S37: 0 | T37: 0 | U37: 0
A38: 2026-06-02 | B38: ke | C38: 2056974 | D38: 254740655805 | E38: 44044.788 | F38: 6097.41 | G38: 0.14 | H38: 6097.27 | I38: 149.81 | J38: 0.14 | K38: 149.67 | L38: 501.65 | M38: 66719 | N38: 1.04 | O38: 138.32 | P38: casino-user | Q38: [50,1000) | R38: B组 | S38: 0 | T38: 10 | U38: 0
A39: 2026-06-02 | B39: ke | C39: 18248033 | D39: 254740725859 | E39: 45899.976 | F39: 852 | G39: 0 | H39: 852 | I39: 81.61 | J39: 0 | K39: 81.61 | L39: 178.23 | M39: 23705 | N39: 169.32 | O39: 22519.56 | P39: aviator-user | Q39: [50,1000) | R39: B组 | S39: 0 | T39: 1130 | U39: 0
A40: 2026-06-02 | B40: ke | C40: 22147505 | D40: 254741082494 | E40: 46110.558 | F40: 218.5 | G40: 0 | H40: 218.5 | I40: -5.94 | J40: 0 | K40: -5.94 | L40: 50.44 | M40: 6708 | N40: 47.91 | O40: 6372.03 | P40: aviator-user | Q40: [50,1000) | R40: B组 | S40: 0 | T40: 320 | U40: 0
... A54: 2026-06-02 | B54: ke | C54: 2395945 | D54: 254798956567 | E54: 44077.367 | F54: 9835.69 | G54: 0 | H54: 9835.69 | I54: -77.61 | J54: 0 | K54: -76.86 | L54: 1203.88 | M54: 160116 | N54: 1122.78 | O54: 149329.74 | P54: aviator-user | Q54: [1000,10w) | R54: B组 | S54: 0 | T54: 7470 | U54: 0
A55: 2026-06-03 | B55: ke | C55: 13103844 | D55: 254112104238 | E55: 45445.171 | F55: 207.31 | G55: 0 | H55: 207.31 | I55: -13.2 | J55: 0 | K55: -13.2 | L55: 71.8 | M55: 9550 | N55: 68.21 | O55: 9071.93 | P55: aviator-user | Q55: [50,1000) | R55: Group B | S55: 0 | T55: 450 | U55: 0
A56: 2026-06-03 | B56: ke | C56: 17904064 | D56: 254115128990 | E56: 45883.499 | F56: 27461.67 | G56: 0.03 | H56: 27461.63 | I56: 1210.67 | J56: 0.01 | K56: 1210.66 | L56: 3040.13 | M56: 404337 | N56: 1092.9 | O56: 145355.7 | P56: aviator-user | Q56: [1000,10w) | R56: Group B | S56: 0 | T56: 7270 | U56: 0
A57: 2026-06-03 | B57: ke | C57: 18904233 | D57: 254115604060 | E57: 45941.621 | F57: 726.11 | G57: 44.53 | H57: 681.58 | I57: -24.86 | J57: -12.01 | K57: -12.85 | L57: 83.43 | M57: 11096 | N57: 3.79 | O57: 504.07 | P57: aviator-user | Q57: [50,1000) | R57: Group B | S57: 0 | T57: 30 | U57: 0
A58: 2026-06-03 | B58: ke | C58: 18695264 | D58: 254116754229 | E58: 45927.757 | F58: 256.14 | G58: 56.91 | H58: 199.23 | I58: 68.28 | J58: 18.8 | K58: 49.47 | L58: 71.87 | M58: 9559 | N58: 0 | O58: 0 | P58: bet&casino-user | Q58: [50,1000) | R58: Group B | S58: 2000 | T58: 0 | U58: 0
A59: 2026-06-03 | B59: ke | C59: 4414404 | D59: 254700102883 | E59: 44314.602 | F59: 344.26 | G59: 0 | H59: 344.26 | I59: 39.23 | J59: 0 | K59: 39.23 | L59: 69.32 | M59: 9220 | N59: 33.11 | O59: 4403.63 | P59: aviator-user | Q59: [50,1000) | R59: Group B | S59: 0 | T59: 220 | U59: 0
A60: 2026-06-03 | B60: ke | C60: 20560484 | D60: 254701121160 | E60: 46027.695 | F60: 2017.58 | G60: 0 | H60: 2017.58 | I60: 55.75 | J60: 0 | K60: 55.75 | L60: 248.23 | M60: 33014 | N60: 115.16 | O60: 15316.28 | P60: casino-user | Q60: [50,1000) | R60: Group B | S60: 0 | T60: 770 | U60: 0
A61: 2026-06-03 | B61: ke | C61: 3763333 | D61: 254701740788 | E61: 44257.146 | F61: 496.35 | G61: 0 | H61: 496.35 | I61: 108.94 | J61: 0 | K61: 108.94 | L61: 158.98 | M61: 21145 | N61: 114.93 | O61: 15285.69 | P61: casino-user | Q61: [50,1000) | R61: Group B | S61: 0 | T61: 760 | U61: 0
A62: 2026-06-03 | B62: ke | C62: 16780144 | D62: 254702516739 | E62: 45802.239 | F62: 948.98 | G62: 50.25 | H62: 898.73 | I62: 22.57 | J62: 42.8 | K62: -20.23 | L62: 149.97 | M62: 19946 | N62: 10.88 | O62: 1447.04 | P62: aviator-user | Q62: [50,1000) | R62: Group B | S62: 0 | T62: 70 | U62: 0
A63: 2026-06-03 | B63: ke | C63: 16962065 | D63: 254702807077 | E63: 45819.586 | F63: 379.84 | G63: 2.98 | H63: 376.86 | I63: -23.51 | J63: 2.62 | K63: -26.14 | L63: 50.4 | M63: 6703 | N63: 1.64 | O63: 218.12 | P63: casino-user | Q63: [50,1000) | R63: Group B | S63: 0 | T63: 10 | U63: 0
A64: 2026-06-03 | B64: ke | C64: 22239065 | D64: 254703334314 | E64: 46116.159 | F64: 2768.14 | G64: 0 | H64: 2768.14 | I64: 74.62 | J64: 0 | K64: 74.62 | L64: 279.17 | M64: 37130 | N64: 265.21 | O64: 35272.93 | P64: casino-user | Q64: [50,1000) | R64: Group B | S64: 0 | T64: 1760 | U64: 0
A65: 2026-06-03 | B65: ke | C65: 21643304 | D65: 254703671166 | E65: 46082.731 | F65: 292.67 | G65: 0 | H65: 292.67 | I65: 21.92 | J65: 0 | K65: 21.92 | L65: 52.08 | M65: 6926 | N65: 36.84 | O65: 4899.72 | P65: aviator-user | Q65: [50,1000) | R65: Group B | S65: 0 | T65: 240 | U65: 0
A66: 2026-06-03 | B66: ke | C66: 17423033 | D66: 254704374937 | E66: 45854.456 | F66: 1084.6 | G66: 0 | H66: 1084.6 | I66: 1.36 | J66: 0 | K66: 1.36 | L66: 70.61 | M66: 9391 | N66: 4.82 | O66: 641.06 | P66: aviator-user | Q66: [50,1000) | R66: Group B | S66: 0 | T66: 30 | U66: 0
...

Sheet C
A1: date | B1: country | C1: userid | D1: username | E1: register_time | F1: Total Stake | G1: Total Stake on Sports | H1: Total Stake on Games | I1: Total GGR | J1: Total Sports GGR | K1: Total Gaming GGR | L1: Total Deposit (usd) | M1: Total Deposit (local) | N1: The latest 90days Deposit (usd) | O1: The latest 90days Deposit (local) | P1: User Preference | Q1: deposit_category | R1: label | S1: No-Deposit Sports Coupon(odd>2.5) | T1: casinobonus | U1: VIP-type | V1: sex | W1: first_name | X1: last_name | Y1: birthday | Z1: temp_birthday | AA1: email
A2: 2026-06-02 | B2: ke | C2: 12428778 | D2: 254113050746 | E2: 45357.687 | F2: 1760.57 | G2: 3.45 | H2: 1757.12 | I2: 107.09 | J2: 3.44 | K2: 103.65 | L2: 264.86 | M2: 35227 | N2: 127.18 | O2: 16914.94 | P2: aviator-user | Q2: [50,1000) | R2: C组 | S2: 0 | T2: 1760 | U2: 0
A3: 2026-06-02 | B3: ke | C3: 14748248 | D3: 254114737055 | E3: 45615.873 | F3: 765.99 | G3: 36.08 | H3: 729.91 | I3: 27.59 | J3: 4.1 | K3: 23.49 | L3: 136.32 | M3: 18130 | N3: 10.61 | O3: 1411.13 | P3: casino-user | Q3: [50,1000) | R3: C组 | S3: 0 | T3: 910 | U3: 0
A4: 2026-06-02 | B4: ke | C4: 13159217 | D4: 254115141583 | E4: 45456.385 | F4: 181.5 | G4: 0.26 | H4: 181.24 | I4: 37.72 | J4: 0.26 | K4: 37.46 | L4: 96.32 | M4: 12811 | N4: 2.37 | O4: 315.21 | P4: aviator-user | Q4: [50,1000) | R4: C组 | S4: 0 | T4: 640 | U4: 0
A5: 2026-06-02 | B5: ke | C5: 22047716 | D5: 254140302868 | E5: 46104.646 | F5: 324.22 | G5: 17.84 | H5: 306.38 | I5: -19.05 | J5: 5.4 | K5: -24.44 | L5: 63.23 | M5: 8410 | N5: 60.07 | O5: 7989.31 | P5: casino-user | Q5: [50,1000) | R5: C组 | S5: 0 | T5: 420 | U5: 0
A6: 2026-06-02 | B6: ke | C6: 22918699 | D6: 254140326664 | E6: 46160.203 | F6: 2.11 | G6: 0 | H6: 2.11 | I6: 2.11 | J6: 0 | K6: 2.11 | L6: 223.83 | M6: 29770 | N6: 212.64 | O6: 28281.12 | P6: aviator-user | Q6: [50,1000) | R6: C组 | S6: 0 | T6: 1490 | U6: 0
A7: 2026-06-02 | B7: ke | C7: 13977406 | D7: 254700013083 | E7: 45567.586 | F7: 2341.03 | G7: 0 | H7: 2341.03 | I7: -0.37 | J7: 0 | K7: -0.37 | L7: 439.8 | M7: 58494 | N7: 113.16 | O7: 15050.28 | P7: aviator-user | Q7: [50,1000) | R7: C组 | S7: 0 | T7: 2920 | U7: 0
A8: 2026-06-02 | B8: ke | C8: 20276979 | D8: 254700114311 | E8: 46014.507 | F8: 429.86 | G8: 0.08 | H8: 429.78 | I8: 71.76 | J8: 0.08 | K8: 71.68 | L8: 87.2 | M8: 11598 | N8: 16.11 | O8: 2142.63 | P8: aviator-user | Q8: [50,1000) | R8: C组 | S8: 0 | T8: 580 | U8: 0
A9: 2026-06-02 | B9: ke | C9: 3173117 | D9: 254701247018 | E9: 44146.382 | F9: 588.26 | G9: 0.97 | H9: 587.29 | I9: 25.4 | J9: 0.97 | K9: 24.43 | L9: 115.35 | M9: 15341 | N9: 0 | O9: 0 | P9: aviator-user | Q9: [50,1000) | R9: C组 | S9: 0 | T9: 770 | U9: 0
A10: 2026-06-02 | B10: ke | C10: 14519156 | D10: 254701620426 | E10: 45603.754 | F10: 571.5 | G10: 19.26 | H10: 552.24 | I10: -17.12 | J10: 16.76 | K10: -33.88 | L10: 168.49 | M10: 22409 | N10: 0 | O10: 0 | P10: casino-user | Q10: [50,1000) | R10: C组 | S10: 0 | T10: 1120 | U10: 0
A11: 2026-06-02 | B11: ke | C11: 16937348 | D11: 254702723630 | E11: 45817.279 | F11: 603.01 | G11: 0 | H11: 603.01 | I11: 21.37 | J11: 0 | K11: 21.37 | L11: 97.29 | M11: 12940 | N11: 0 | O11: 0 | P11: casino-user | Q11: [50,1000) | R11: C组 | S11: 0 | T11: 650 | U11: 0
A12: 2026-06-02 | B12: ke | C12: 13783887 | D12: 254704359713 | E12: 45555.596 | F12: 1224.1 | G12: 226.03 | H12: 998.07 | I12: 170.61 | J12: 150.96 | K12: 19.65 | L12: 274.59 | M12: 36521 | N12: 28.23 | O12: 3754.59 | P12: bet&casino-user | Q12: [50,1000) | R12: C组 | S12: 2000 | T12: 915 | U12: 0
A13: 2026-06-02 | B13: ke | C13: 10427179 | D13: 254704668179 | E13: 45150.346 | F13: 373.07 | G13: 0.26 | H13: 372.81 | I13: 22.61 | J13: 0.21 | K13: 22.4 | L13: 51.17 | M13: 6806 | N13: 27.16 | O13: 3612.28 | P13: casino-user | Q13: [50,1000) | R13: C组 | S13: 0 | T13: 340 | U13: 0
... A66: 2026-06-02 | B66: ke | C66: 11333228 | D66: 254729277934 | E66: 45245.554 | F66: 3469.83 | G66: 6.66 | H66: 3462.79 | I66: 237.49 | J66: -9.31 | K66: 246.8 | L66: 901.62 | M66: 119915 | N66: 474.38 | O66: 63092.54 | P66: aviator-user | Q66: [50,1000) | R66: C组 | S66: 0 | T66: 6000 | U66: 0
A67: 2026-06-02 | B67: ke | C67: 4704828 | D67: 254729889133 | E67: 44359.91 | F67: 438661.11 | G67: 232.41 | H67: 438428.7 | I67: 18151.78 | J67: 57.28 | K67: 18094.5 | L67: 63804.09 | M67: 8485944 | N67: 11477.45 | O67: 1526500.9 | P67: casino-user | Q67: [1000,10w) | R67: C组 | S67: 0 | T67: 30000 | U67: 1 | V67: 1
A68: 2026-06-02 | B68: ke | C68: 12760006 | D68: 254740307312 | E68: 45401.432 | F68: 1858.16 | G68: 0 | H68: 1858.16 | I68: 227.47 | J68: 0 | K68: 227.47 | L68: 819.32 | M68: 108970 | N68: 334.44 | O68: 44480.52 | P68: aviator-user | Q68: [50,1000) | R68: C组 | S68: 0 | T68: 5450 | U68: 0
A69: 2026-06-02 | B69: ke | C69: 2021806 | D69: 254740727423 | E69: 44043.439 | F69: 5102.93 | G69: 0.76 | H69: 5102.17 | I69: 536.4 | J69: 0.76 | K69: 535.64 | L69: 1310.04 | M69: 174235 | N69: 1359 | O69: 180747 | P69: casino-user | Q69: [1000,10w) | R69: C组 | S69: 0 | T69: 8710 | U69: 0
A70: 2026-06-02 | B70: ke | C70: 18622676 | D70: 254743496752 | E70: 45923.625 | F70: 223.23 | G70: 6.36 | H70: 216.87 | I70: 9.81 | J70: 3.72 | K70: 6.1 | L70: 93.01 | M70: 12370 | N70: 14.46 | O70: 1923.18 | P70: aviator-user | Q70: [50,1000) | R70: C组 | S70: 0 | T70: 620 | U70: 0
A71: 2026-06-02 | B71: ke | C71: 16156727 | D71: 254745459474 | E71: 45755.784 | F71: 1078.49 | G71: 13.62 | H71: 1064.86 | I71: 143.82 | J71: 10.33 | K71: 133.49 | L71: 291.84 | M71: 38815 | N71: 101.21 | O71: 13460.93 | P71: aviator-user | Q71: [50,1000) | R71: C组 | S71: 0 | T71: 1940 | U71: 0
A72: 2026-06-02 | B72: ke | C72: 14917849 | D72: 254745965971 | E72: 45628.647 | F72: 939.49 | G72: 0.14 | H72: 939.35 | I72: 47.79 | J72: 0.13 | K72: 47.66 | L72: 133.47 | M72: 17751 | N72: 20.12 | O72: 2675.96 | P72: aviator-user | Q72: [50,1000) | R72: C组 | S72: 0 | T72: 890 | U72: 0
A73: 2026-06-02 | B73: ke | C73: 13205388 | D73: 254748105090 | E73: 45465.487 | F73: 701.44 | G73: 0 | H73: 701.44 | I73: 18.92 | J73: 0 | K73: 18.92 | L73: 319.1 | M73: 42440 | N73: 59.29 | O73: 7885.57 | P73: aviator-user | Q73: [50,1000) | R73: C组 | S73: 0 | T73: 2120 | U73: 0
A74: 2026-06-02 | B74: ke | C74: 9013878 | D74: 254748400412 | E74: 44876.259 | F74: 539.63 | G74: 0.38 | H74: 539.25 | I74: 2.01 | J74: 0.38 | K74: 1.62 | L74: 53.22 | M74: 7078 | N74: 2.14 | O74: 284.62 | P74: aviator-user | Q74: [50,1000) | R74: C组 | S74: 0 | T74: 350 | U74: 0
A75: 2026-06-02 | B75: ke | C75: 17349408 | D75: 254748638509 | E75: 45848.472 | F75: 2260.17 | G75: 1.32 | H75: 2258.85 | I75: 79.89 | J75: 0.04 | K75: 79.85 | L75: 388.47 | M75: 51667 | N75: 57.44 | O75: 7639.52 | P75: aviator-user | Q75: [50,1000) | R75: C组 | S75: 0 | T75: 2580 | U75: 0
A76: 2026-06-02 | B76: ke | C76: 19113799 | D76: 254752862759 | E76: 45955.228 | F76: 461.52 | G76: 2.68 | H76: 458.85 | I76: -4.57 | J76: 2.68 | K76: -7.25 | L76: 124.89 | M76: 16611 | N76: 61.23 | O76: 8143.59 | P76: aviator-user | Q76: [50,1000) | R76: C组 | S76: 0 | T76: 830 | U76: 0
A77: 2026-06-02 | B77: ke | C77: 9307057 | D77: 254753067729 | E77: 44926.844 | F77: 15348.81 | G77: 0.02 | H77: 15348.8 | I77: 721.33 | J77: 0.02 | K77: 721.32 | L77: 3049.24 | M77: 405549 | N77: 583.07 | O77: 77548.31 | P77: casino-user | Q77: [1000,10w) | R77: C组 | S77: 0 | T77: 20280 | U77: 0
A78: 2026-06-02 | B78: ke | C78: 13716069 | D78: 254757853772 | E78: 45549.847 | F78: 296.53 | G78: 0 | H78: 296.53 | I78: 15.32 | J78: 0 | K78: 15.32 | L78: 123.23 | M78: 16390 | N78: 20.71 | O78: 2754.43 | P78: aviator-user | Q78: [50,1000) | R78: C组 | S78: 0 | T78: 820 | U78: 0
A79: 2026-06-02 | B79: ke | C79: 16267439 | D79: 254758619701 | E79: 45762.896 | F79: 486.03 | G79: 0.02 | H79: 486.02 | I79: 24.38 | J79: 0.02 | K79: 24.36 | L79: 53.35 | M79: 7095 | N79: 13.41 | O79: 1783.53 | P79: casino-user | Q79: [50,1000) | R79: C组 | S79: 0 | T79: 350 | U79: 0
... A97: 2026-06-02 | B97: ke | C97: 21299267 | D97: 254798946247 | E97: 46065.874 | F97: 349.32 | G97: 0 | H97: 349.32 | I97: -175.75 | J97: 0 | K97: -175.75 | L97: 152.98 | M97: 20347 | N97: 107.28 | O97: 14268.24 | P97: aviator-user | Q97: [50,1000) | R97: C组 | S97: 0 | T97: 1020 | U97: 0
A98: 2026-06-03 | B98: ke | C98: 14114747 | D98: 254110233502 | E98: 45577.857 | F98: 1131.35 | G98: 0.43 | H98: 1130.92 | I98: 91.99 | J98: 0.43 | K98: 91.56 | L98: 266.69 | M98: 35470 | N98: 89.3 | O98: 11876.9 | P98: casino-user | Q98: [50,1000) | R98: Group C | S98: 0 | T98: 1770 | U98: 0
A99: 2026-06-03 | B99: ke | C99: 20922247 | D99: 254110361556 | E99: 46044.961 | F99: 3011.85 | G99: 0 | H99: 3011.85 | I99: 211.38 | J99: 0 | K99: 211.38 | L99: 478.41 | M99: 63628 | N99: 417.69 | O99: 55552.77 | P99: casino-user | Q99: [50,1000) | R99: Group C | S99: 0 | T99: 3180 | U99: 0
A100: 2026-06-03 | B100: ke | C100: 5331377 | D100: 254111398591 | E100: 44451.276 | F100: 3346.43 | G100: 0.8 | H100: 3345.63 | I100: -69.71 | J100: 0.8 | K100: -70.52 | L100: 782.24 | M100: 104038 | N100: 13.21 | O100: 1756.93 | P100: casino-user | Q100: [50,1000) | R100: Group C | S100: 0 | T100: 5200 | U100: 0
A101: 2026-06-03 | B101: ke | C101: 16383687 | D101: 254112866475 | E101: 45771.381 | F101: 3019.74 | G101: 0 | H101: 3019.74 | I101: -4.36 | J101: 0 | K101: -4.36 | L101: 309.92 | M101: 41220 | N101: 0 | O101: 0 | P101: casino-user | Q101: [50,1000) | R101: Group C | S101: 0 | T101: 2060 | U101: 0
A102: 2026-06-03 | B102: ke | C102: 21072016 | D102: 254113241000 | E102: 46053.904 | F102: 1367.73 | G102: 0 | H102: 1367.73 | I102: 42.04 | J102: 0 | K102: 42.04 | L102: 138.35 | M102: 18401 | N102: 68.52 | O102: 9113.16 | P102: aviator-user | Q102: [50,1000) | R102: Group C | S102: 0 | T102: 920 | U102: 0
A103: 2026-06-03 | B103: ke | C103: 22093859 | D103: 254113335557 | E103: 46107.396 | F103: 14200.11 | G103: 0 | H103: 14200.11 | I103: 666.22 | J103: 0 | K103: 666.22 | L103: 1059.59 | M103: 140925 | N103: 1006.61 | O103: 133879.13 | P103: aviator-user | Q103: [1000,10w) | R103: Group C | S103: 0 | T103: 7050 | U103: 0
A104: 2026-06-03 | B104: ke | C104: 19733687 | D104: 254113615115 | E104: 45988.459 | F104: 5134.6 | G104: 0.42 | H104: 5134.18 | I104: -43.99 | J104: -0.24 | K104: -43.75 | L104: 508.97 | M104: 67693 | N104: 6.11 | O104: 812.63 | P104: casino-user | Q104: [50,1000) | R104: Group C | S104: 0 | T104: 3380 | U104: 0
A105: 2026-06-03 | B105: ke | C105: 21200368 | D105: 254116021075 | E105: 46060.743 | F105: 1494.79 | G105: 0 | H105: 1494.79 | I105: 103.84 | J105: 0 | K105: 103.84 | L105: 589.61 | M105: 78418 | N105: 241.11 | O105: 32067.63 | P105: aviator-user | Q105: [50,1000) | R105: Group C | S105: 0 | T105: 3920 | U105: 0
A106: 2026-06-03 | B106: ke | C106: 16251086 | D106: 254116249274 | E106: 45761.842 | F106: 627.96 | G106: 0 | H106: 627.96 | I106: 123.67 | J106: 0 | K106: 123.67 | L106: 326 | M106: 43358 | N106: 57.48 | O106: 7644.84 | P106: aviator-user | Q106: [50,1000) | R106: Group C | S106: 0 | T106: 2170 | U106: 0
A107: 2026-06-03 | B107: ke | C107: 18131309 | D107: 254117010052 | E107: 45894.31 | F107: 817.12 | G107: 0 | H107: 817.12 | I107: 6.43 | J107: 0 | K107: 6.43 | L107: 64.41 | M107: 8567 | N107: 0 | O107: 0 | P107: aviator-user | Q107: [50,1000) | R107: Group C | S107: 0 | T107: 430 | U107: 0
A108: 2026-06-03 | B108: ke | C108: 20259796 | D108: 254117507840 | E108: 46013.562 | F108: 381.69 | G108: 0.5 | H108: 381.19 | I108: -64.44 | J108: 0.2 | K108: -64.64 | L108: 145.99 | M108: 19417 | N108: 8.44 | O108: 1122.52 | P108: aviator-user | Q108: [50,1000) | R108: Group C | S108: 0 | T108: 970 | U108: 0
A109: 2026-06-03 | B109: ke | C109: 22517226 | D109: 254117789395 | E109: 46132.432 | F109: 497.07 | G109: 0.34 | H109: 496.73 | I109: 103.29 | J109: 0.34 | K109: 102.95 | L109: 122.47 | M109: 16288 | N109: 116.34 | O109: 15473.22 | P109: aviator-user | Q109: [50,1000) | R109: Group C | S109: 0 | T109: 810 | U109: 0
...

Sheet combinate
A1: username | B1: label
A2: 254115464651 | B2: Group A
A3: 254116255629 | B3: Group A
A4: 254116611542 | B4: Group A
A5: 254140047631 | B5: Group A
A6: 254140414468 | B6: Group A
A7: 254141464090 | B7: Group A
A8: 254700785323 | B8: Group A
A9: 254703325859 | B9: Group A
A10: 254703581163 | B10: Group A
A11: 254707025433 | B11: Group A
A12: 254707829195 | B12: Group A
A13: 254710659278 | B13: Group A
... A889: 254799286851 | B889: Group C

Sheet Sheet1
A2: 计数项:用户手机号 | B2: 是否回归
A3: label | C3: 是 | D3: 总计 | E3: 回归率
A4: Group A | C4: 140 | D4: 324 | E4: =C4/D4 -> 0.43209877
A5: Group B | C5: 66 | D5: 106 | E5: =C5/D5 -> 0.62264151
A6: Group C | C6: 267 | D6: 458 | E6: =C6/D6 -> 0.58296943
A7: 总计 | C7: 473 | D7: 888 | E7: =C7/D7 -> 0.53265766
A9: 计数项:用户手机号 | B9: 是否有效回归
A10: label | B10: 否 | C10: 是 | D10: 总计 | E10: 漏斗有效 | F10: 有效回归率
A11: Group A | B11: 248 | C11: 76 | D11: 324 | E11: =GETPIVOTDATA("用户手机号",$A$9,"label","Group A","是否有效回归","是")/C4 -> 0.54285714 | F11: =GETPIVOTDATA("用户手机号",$A$9,"label","Group A","是否有效回归","是")/GETPIVOTDATA("用户手机号",$A$9,"label","Group A") -> 0.2345679
A12: Group B | B12: 58 | C12: 48 | D12: 106 | E12: =GETPIVOTDATA("用户手机号",$A$9,"label","Group B","是否有效回归","是")/C5 -> 0.72727273 | F12: =GETPIVOTDATA("用户手机号",$A$9,"label","Group B","是否有效回归","是")/GETPIVOTDATA("用户手机号",$A$9,"label","Group B") -> 0.45283019
A13: Group C | B13: 265 | C13: 193 | D13: 458 | E13: =GETPIVOTDATA("用户手机号",$A$9,"label","Group C","是否有效回归","是")/C6 -> 0.72284644 | F13: =GETPIVOTDATA("用户手机号",$A$9,"label","Group C","是否有效回归","是")/GETPIVOTDATA("用户手机号",$A$9,"label","Group C") -> 0.42139738
A14: 总计 | B14: 571 | C14: 317 | D14: 888 | E14: =GETPIVOTDATA("用户手机号",$A$9,"是否有效回归","是")/C7 -> 0.67019027 | F14: =GETPIVOTDATA("用户手机号",$A$9,"是否有效回归","是")/GETPIVOTDATA("用户手机号",$A$9) -> 0.35698198
A16: 是否有效回归 | B16: 是
A18: label | B18: 计数项:是否有效回归 | C18: 求和项:总投注流水（本地货币） | D18: 求和项:全部ggr（本地货币） | E18: 求和项:充值金额（本地货币）
A19: Group A | B19: 76 | C19: 1617072.4 | D19: 174503.77 | E19: 177724.3
A20: Group B | B20: 48 | C20: 314525.57 | D20: 21977.2 | E20: 43287
A21: Group C | B21: 193 | C21: 2260184.2 | D21: 167864.51 | E21: 343634.85
A22: 总计 | B22: 317 | C22: 4191782.1 | D22: 364345.48 | E22: 564646.15
C24: =GETPIVOTDATA("求和项:总投注流水（本地货币）",$A$18,"label","Group A")/GETPIVOTDATA("计数项:是否有效回归",$A$18,"label","Group A") -> 21277.268 | D24: =GETPIVOTDATA("求和项:全部ggr（本地货币）",$A$18,"label","Group A")/GETPIVOTDATA("计数项:是否有效回归",$A$18,"label","Group A") -> 2296.1022 | E24: =GETPIVOTDATA("求和项:充值金额（本地货币）",$A$18,"label","Group A")/GETPIVOTDATA("计数项:是否有效回归",$A$18,"label","Group A") -> 2338.4776
C25: =GETPIVOTDATA("求和项:总投注流水（本地货币）",$A$18,"label","Group B")/GETPIVOTDATA("计数项:是否有效回归",$A$18,"label","Group B") -> 6552.616 | D25: =GETPIVOTDATA("求和项:全部ggr（本地货币）",$A$18,"label","Group B")/GETPIVOTDATA("计数项:是否有效回归",$A$18,"label","Group B") -> 457.85833 | E25: =GETPIVOTDATA("求和项:充值金额（本地货币）",$A$18,"label","Group B")/GETPIVOTDATA("计数项:是否有效回归",$A$18,"label","Group B") -> 901.8125
C26: =GETPIVOTDATA("求和项:总投注流水（本地货币）",$A$18,"label","Group C")/GETPIVOTDATA("计数项:是否有效回归",$A$18,"label","Group C") -> 11710.799 | D26: =GETPIVOTDATA("求和项:全部ggr（本地货币）",$A$18,"label","Group C")/GETPIVOTDATA("计数项:是否有效回归",$A$18,"label","Group C") -> 869.7643 | E26: =GETPIVOTDATA("求和项:充值金额（本地货币）",$A$18,"label","Group C")/GETPIVOTDATA("计数项:是否有效回归",$A$18,"label","Group C") -> 1780.4915
C27: =GETPIVOTDATA("求和项:总投注流水（本地货币）",$A$18)/GETPIVOTDATA("计数项:是否有效回归",$A$18) -> 13223.287 | D27: =GETPIVOTDATA("求和项:全部ggr（本地货币）",$A$18)/GETPIVOTDATA("计数项:是否有效回归",$A$18) -> 1149.3548 | E27: =GETPIVOTDATA("求和项:充值金额（本地货币）",$A$18)/GETPIVOTDATA("计数项:是否有效回归",$A$18) -> 1781.2181

Sheet 总表
A1: label | B1: 用户手机号 | C1: 用户id | D1: 最后登录时间 | E1: 是否有效回归 | F1: 总投注流水（usd） | G1: 总投注流水（本地货币） | H1: 体育投注流水（本地货币） | I1: 游戏投注流水（本地货币） | J1: 体育ggr（本地货币） | K1: 游戏ggr（本地货币） | L1: 全部ggr（usd） | M1: 全部ggr（本地货币） | N1: 充值金额（usd） | O1: 充值金额（本地货币） | P1: 提现金额（usd） | Q1: 提现金额（本地货币）
A2: =VLOOKUP(B2,combinate!A:B,2,FALSE) -> Group A | B2: 254725223000 | C2: 155980 | D2: 46182.808 | E2: 是 | F2: 0.53 | G2: 70 | H2: 0 | I2: 70 | J2: 0 | K2: 50.8 | L2: 0.38 | M2: 50.8 | N2: 0.36 | O2: 47.5 | P2: 0 | Q2: 0
A3: =VLOOKUP(B3,combinate!A:B,2,FALSE) -> Group B | B3: 254718564157 | C3: 173655 | D3: 46184.199 | E3: 是 | F3: 11.11 | G3: 1477 | H3: 0 | I3: 1477 | J3: 0 | K3: 543.55 | L3: 4.09 | M3: 543.55 | N3: 3.57 | O3: 475 | P3: 0 | Q3: 0
A4: =VLOOKUP(B4,combinate!A:B,2,FALSE) -> Group A | B4: 254724373010 | C4: 531341 | D4: 46183.798 | E4: 是 | F4: 24.51 | G4: 3260 | H4: 0 | I4: 3260 | J4: 0 | K4: 1038.75 | L4: 7.81 | M4: 1038.75 | N4: 7.86 | O4: 1045 | P4: 0 | Q4: 0
A5: =VLOOKUP(B5,combinate!A:B,2,FALSE) -> Group C | B5: 254742176619 | C5: 618626 | D5: 46183.603 | E5: 是 | F5: 2.57 | G5: 341.22 | H5: 0 | I5: 341.22 | J5: 0 | K5: 42.75 | L5: 0.32 | M5: 42.75 | N5: 0.32 | O5: 42.75 | P5: 0 | Q5: 0
A6: =VLOOKUP(B6,combinate!A:B,2,FALSE) -> Group C | B6: 254706761895 | C6: 2276847 | D6: 46178.495 | E6: 是 | F6: 0.05 | G6: 6.4 | H6: 0 | I6: 6.4 | J6: 0 | K6: 6.4 | L6: 0.05 | M6: 6.4 | N6: 0 | O6: 0 | P6: 0 | Q6: 0
A7: =VLOOKUP(B7,combinate!A:B,2,FALSE) -> Group C | B7: 254748338772 | C7: 2384066 | D7: 46184.417 | E7: 是 | F7: 23.58 | G7: 3136.05 | H7: 0 | I7: 3136.05 | J7: 0 | K7: 624.4 | L7: 4.69 | M7: 624.4 | N7: 4.69 | O7: 624.15 | P7: 0 | Q7: 0
A8: =VLOOKUP(B8,combinate!A:B,2,FALSE) -> Group C | B8: 254719541682 | C8: 2986269 | D8: 46177.738 | E8: 是 | F8: 17.2 | G8: 2288 | H8: 120 | I8: 2168 | J8: 120 | K8: -225.1 | L8: -0.79 | M8: -105.1 | N8: 1.43 | O8: 190 | P8: 7.52 | Q8: 1000
A9: =VLOOKUP(B9,combinate!A:B,2,FALSE) -> Group B | B9: 254701740788 | C9: 3763333 | D9: 46178.241 | E9: 是 | F9: 245.02 | G9: 32588.15 | H9: 0 | I9: 32588.15 | J9: 0 | K9: 4167.85 | L9: 31.34 | M9: 4167.85 | N9: 26.42 | O9: 3514.05 | P9: 0 | Q9: 0
A10: =VLOOKUP(B10,combinate!A:B,2,FALSE) -> Group C | B10: 254714852588 | C10: 8544378 | D10: 46178.516 | E10: 否 | F10: 0 | G10: 0 | H10: 0 | I10: 0 | J10: 0 | K10: 0 | L10: 0 | M10: 0 | N10: 0 | O10: 0 | P10: 0 | Q10: 0
A11: =VLOOKUP(B11,combinate!A:B,2,FALSE) -> Group A | B11: 254706989984 | C11: 10554370 | D11: 46162.339 | E11: 否 | F11: 0 | G11: 0 | H11: 0 | I11: 0 | J11: 0 | K11: 0 | L11: 0 | M11: 0 | N11: 0 | O11: 0 | P11: 0 | Q11: 0
A12: =VLOOKUP(B12,combinate!A:B,2,FALSE) -> Group B | B12: 254794321132 | C12: 10895675 | D12: 46179.32 | E12: 是 | F12: 0.71 | G12: 95 | H12: 95 | I12: 0 | J12: 95 | K12: 0 | L12: 0.71 | M12: 95 | N12: 0.71 | O12: 95 | P12: 0 | Q12: 0
A13: =VLOOKUP(B13,combinate!A:B,2,FALSE) -> Group C | B13: 254718004064 | C13: 10962028 | D13: 46161.413 | E13: 否 | F13: 0 | G13: 0 | H13: 0 | I13: 0 | J13: 0 | K13: 0 | L13: 0 | M13: 0 | N13: 0 | O13: 0 | P13: 0 | Q13: 0
... A889: =VLOOKUP(B889,combinate!A:B,2,FALSE) -> Group A | B889: 254729893155 | C889: 20267270 | D889: 46163.17 | E889: 否 | F889: 0 | G889: 0 | H889: 0 | I889: 0 | J889: 0 | K889: 0 | L889: 0 | M889: 0 | N889: 0 | O889: 0 | P889: 0 | Q889: 0
